Workbook

Sheet 📖 使用说明
B2: 万马多新豪 v62 — 分析模板使用指南
B3: 配合系统导出的 Excel 文件使用 · 纯数据 · 不预测
B5: 📋 本模板包含以下工作表
B7: 📖 使用说明 | C7: 你现在在这里。说明各表用途和操作流程。
B8: 📌 命中追踪 | C8: 每期记录你选的号码 + 实际开奖 → 自动统计命中率、方法效果。
B9: 🔬 方法验证 | C9: 用 COUNTIFS 公式深挖各方法的真实成功率，避免「感觉有效」的偏差。
B10: 📊 月度总结 | C10: 按月汇总命中率、花费、回报，找出你最强的月份和市场。
B11: 💡 透视表指引 | C11: 手把手说明如何在导出的历史数据上建立数据透视表做更深分析。
B13: 🔄 推荐工作流程（每期）
B14: ① 开奖前 | C14: 在系统里完成分析 → 选出 5-10 个候选号码
B15: ② 记录选号 | C15: 在「命中追踪」表填入日期、市场、你选的号码、使用的方法
B16: ③ 开奖后 | C16: 填入实际头/二/三奖号码 → 命中列自动变色
B17: ④ 每月一次 | C17: 看「月度总结」表的命中率变化 → 找规律
B18: ⑤ 每季一次 | C18: 看「方法验证」表 → 停用效果差的方法，加强有效的
B20: ⚠️ 重要提醒
B21: • 彩票属于随机事件，本模板只是帮助你「有纪律地记录决策」，无法提高中奖概率。
B22: • 命中追踪的意义不是证明你会赢，而是找出哪些方法让你输得少一点。
B23: • 建议连续使用至少 3 个月，样本太少的统计没有意义。
B24: • 每次开奖后务必填写实际结果，否则命中率统计会失效。

Sheet 📌 命中追踪
A2: 📌 命中追踪表 — 每期选号 vs 实际开奖 | Q2: 📊 实时统计
A3: # | B3: 日期 | C3: 市场 | D3: ← 我选的号码（最多5个）→ | I3: ← 实际开奖 → | L3: 命中 | M3: 中奖号 | N3: 方法 | O3: 备注
A4: # | B4: 日期 | C4: 市场 | D4: 选号1 | E4: 选号2 | F4: 选号3 | G4: 选号4 | H4: 选号5 | I4: 头奖 | J4: 二奖 | K4: 三奖 | L4: 命中? | M4: 中奖号 | N4: 方法 | O4: 备注 | Q4: 总期数 | R4: =COUNTA(B5:B104)
A5: 1 | L5: =IF(COUNTA(D5:H5)=0,"",IF(SUMPRODUCT((ISNUMBER(MATCH(IF(D5:H5<>"",D5:H5,0),IF(I5:K5<>"",I5:K5,999999),0)))*1)>0,"✅ 命中","❌")) | M5: =IF(L5="✅ 命中",IFERROR(INDEX(D5:H5,MATCH(1,ISNUMBER(MATCH(IF(D5:H5<>"",D5:H5,0),IF(I5:K5<>"",I5:K5,999999),0))*1,0)),""),"--") | Q5: 有选号期数 | R5: =SUMPRODUCT(--(MMULT(--(D5:H104<>""),{1,1,1,1,1})>0))
A6: 2 | L6: =IF(COUNTA(D6:H6)=0,"",IF(SUMPRODUCT((ISNUMBER(MATCH(IF(D6:H6<>"",D6:H6,0),IF(I6:K6<>"",I6:K6,999999),0)))*1)>0,"✅ 命中","❌")) | M6: =IF(L6="✅ 命中",IFERROR(INDEX(D6:H6,MATCH(1,ISNUMBER(MATCH(IF(D6:H6<>"",D6:H6,0),IF(I6:K6<>"",I6:K6,999999),0))*1,0)),""),"--") | Q6: 命中次数 | R6: =COUNTIF(L5:L104,"✅ 命中")
A7: 3 | L7: =IF(COUNTA(D7:H7)=0,"",IF(SUMPRODUCT((ISNUMBER(MATCH(IF(D7:H7<>"",D7:H7,0),IF(I7:K7<>"",I7:K7,999999),0)))*1)>0,"✅ 命中","❌")) | M7: =IF(L7="✅ 命中",IFERROR(INDEX(D7:H7,MATCH(1,ISNUMBER(MATCH(IF(D7:H7<>"",D7:H7,0),IF(I7:K7<>"",I7:K7,999999),0))*1,0)),""),"--") | Q7: 命中率 | R7: =IFERROR(COUNTIF(L5:L104,"✅ 命中")/COUNTIF(L5:L104,"<>"),0)
A8: 4 | L8: =IF(COUNTA(D8:H8)=0,"",IF(SUMPRODUCT((ISNUMBER(MATCH(IF(D8:H8<>"",D8:H8,0),IF(I8:K8<>"",I8:K8,999999),0)))*1)>0,"✅ 命中","❌")) | M8: =IF(L8="✅ 命中",IFERROR(INDEX(D8:H8,MATCH(1,ISNUMBER(MATCH(IF(D8:H8<>"",D8:H8,0),IF(I8:K8<>"",I8:K8,999999),0))*1,0)),""),"--")
A9: 5 | L9: =IF(COUNTA(D9:H9)=0,"",IF(SUMPRODUCT((ISNUMBER(MATCH(IF(D9:H9<>"",D9:H9,0),IF(I9:K9<>"",I9:K9,999999),0)))*1)>0,"✅ 命中","❌")) | M9: =IF(L9="✅ 命中",IFERROR(INDEX(D9:H9,MATCH(1,ISNUMBER(MATCH(IF(D9:H9<>"",D9:H9,0),IF(I9:K9<>"",I9:K9,999999),0))*1,0)),""),"--") | Q9: ─ 按方法 ─
A10: 6 | L10: =IF(COUNTA(D10:H10)=0,"",IF(SUMPRODUCT((ISNUMBER(MATCH(IF(D10:H10<>"",D10:H10,0),IF(I10:K10<>"",I10:K10,999999),0)))*1)>0,"✅ 命中","❌")) | M10: =IF(L10="✅ 命中",IFERROR(INDEX(D10:H10,MATCH(1,ISNUMBER(MATCH(IF(D10:H10<>"",D10:H10,0),IF(I10:K10<>"",I10:K10,999999),0))*1,0)),""),"--") | Q10: 数根链 | R10: =IFERROR(COUNTIFS(N5:N104,"数根链",L5:L104,"✅ 命中")/COUNTIF(N5:N104,"数根链"),0)
A11: 7 | L11: =IF(COUNTA(D11:H11)=0,"",IF(SUMPRODUCT((ISNUMBER(MATCH(IF(D11:H11<>"",D11:H11,0),IF(I11:K11<>"",I11:K11,999999),0)))*1)>0,"✅ 命中","❌")) | M11: =IF(L11="✅ 命中",IFERROR(INDEX(D11:H11,MATCH(1,ISNUMBER(MATCH(IF(D11:H11<>"",D11:H11,0),IF(I11:K11<>"",I11:K11,999999),0))*1,0)),""),"--") | Q11: 配对分析 | R11: =IFERROR(COUNTIFS(N5:N104,"配对分析",L5:L104,"✅ 命中")/COUNTIF(N5:N104,"配对分析"),0)
A12: 8 | L12: =IF(COUNTA(D12:H12)=0,"",IF(SUMPRODUCT((ISNUMBER(MATCH(IF(D12:H12<>"",D12:H12,0),IF(I12:K12<>"",I12:K12,999999),0)))*1)>0,"✅ 命中","❌")) | M12: =IF(L12="✅ 命中",IFERROR(INDEX(D12:H12,MATCH(1,ISNUMBER(MATCH(IF(D12:H12<>"",D12:H12,0),IF(I12:K12<>"",I12:K12,999999),0))*1,0)),""),"--") | Q12: 冷热库 | R12: =IFERROR(COUNTIFS(N5:N104,"冷热库",L5:L104,"✅ 命中")/COUNTIF(N5:N104,"冷热库"),0)
A13: 9 | L13: =IF(COUNTA(D13:H13)=0,"",IF(SUMPRODUCT((ISNUMBER(MATCH(IF(D13:H13<>"",D13:H13,0),IF(I13:K13<>"",I13:K13,999999),0)))*1)>0,"✅ 命中","❌")) | M13: =IF(L13="✅ 命中",IFERROR(INDEX(D13:H13,MATCH(1,ISNUMBER(MATCH(IF(D13:H13<>"",D13:H13,0),IF(I13:K13<>"",I13:K13,999999),0))*1,0)),""),"--") | Q13: 四步向导 | R13: =IFERROR(COUNTIFS(N5:N104,"四步向导",L5:L104,"✅ 命中")/COUNTIF(N5:N104,"四步向导"),0)
A14: 10 | L14: =IF(COUNTA(D14:H14)=0,"",IF(SUMPRODUCT((ISNUMBER(MATCH(IF(D14:H14<>"",D14:H14,0),IF(I14:K14<>"",I14:K14,999999),0)))*1)>0,"✅ 命中","❌")) | M14: =IF(L14="✅ 命中",IFERROR(INDEX(D14:H14,MATCH(1,ISNUMBER(MATCH(IF(D14:H14<>"",D14:H14,0),IF(I14:K14<>"",I14:K14,999999),0))*1,0)),""),"--") | Q14: 工作台 | R14: =IFERROR(COUNTIFS(N5:N104,"工作台",L5:L104,"✅ 命中")/COUNTIF(N5:N104,"工作台"),0)
A15: 11 | L15: =IF(COUNTA(D15:H15)=0,"",IF(SUMPRODUCT((ISNUMBER(MATCH(IF(D15:H15<>"",D15:H15,0),IF(I15:K15<>"",I15:K15,999999),0)))*1)>0,"✅ 命中","❌")) | M15: =IF(L15="✅ 命中",IFERROR(INDEX(D15:H15,MATCH(1,ISNUMBER(MATCH(IF(D15:H15<>"",D15:H15,0),IF(I15:K15<>"",I15:K15,999999),0))*1,0)),""),"--") | Q15: 点数区间 | R15: =IFERROR(COUNTIFS(N5:N104,"点数区间",L5:L104,"✅ 命中")/COUNTIF(N5:N104,"点数区间"),0)
A16: 12 | L16: =IF(COUNTA(D16:H16)=0,"",IF(SUMPRODUCT((ISNUMBER(MATCH(IF(D16:H16<>"",D16:H16,0),IF(I16:K16<>"",I16:K16,999999),0)))*1)>0,"✅ 命中","❌")) | M16: =IF(L16="✅ 命中",IFERROR(INDEX(D16:H16,MATCH(1,ISNUMBER(MATCH(IF(D16:H16<>"",D16:H16,0),IF(I16:K16<>"",I16:K16,999999),0))*1,0)),""),"--") | Q16: 条件筛选 | R16: =IFERROR(COUNTIFS(N5:N104,"条件筛选",L5:L104,"✅ 命中")/COUNTIF(N5:N104,"条件筛选"),0)
A17: 13 | L17: =IF(COUNTA(D17:H17)=0,"",IF(SUMPRODUCT((ISNUMBER(MATCH(IF(D17:H17<>"",D17:H17,0),IF(I17:K17<>"",I17:K17,999999),0)))*1)>0,"✅ 命中","❌")) | M17: =IF(L17="✅ 命中",IFERROR(INDEX(D17:H17,MATCH(1,ISNUMBER(MATCH(IF(D17:H17<>"",D17:H17,0),IF(I17:K17<>"",I17:K17,999999),0))*1,0)),""),"--") | Q17: 人工判断 | R17: =IFERROR(COUNTIFS(N5:N104,"人工判断",L5:L104,"✅ 命中")/COUNTIF(N5:N104,"人工判断"),0)
A18: 14 | L18: =IF(COUNTA(D18:H18)=0,"",IF(SUMPRODUCT((ISNUMBER(MATCH(IF(D18:H18<>"",D18:H18,0),IF(I18:K18<>"",I18:K18,999999),0)))*1)>0,"✅ 命中","❌")) | M18: =IF(L18="✅ 命中",IFERROR(INDEX(D18:H18,MATCH(1,ISNUMBER(MATCH(IF(D18:H18<>"",D18:H18,0),IF(I18:K18<>"",I18:K18,999999),0))*1,0)),""),"--")
A19: 15 | L19: =IF(COUNTA(D19:H19)=0,"",IF(SUMPRODUCT((ISNUMBER(MATCH(IF(D19:H19<>"",D19:H19,0),IF(I19:K19<>"",I19:K19,999999),0)))*1)>0,"✅ 命中","❌")) | M19: =IF(L19="✅ 命中",IFERROR(INDEX(D19:H19,MATCH(1,ISNUMBER(MATCH(IF(D19:H19<>"",D19:H19,0),IF(I19:K19<>"",I19:K19,999999),0))*1,0)),""),"--") | Q19: ─ 按市场 ─
A20: 16 | L20: =IF(COUNTA(D20:H20)=0,"",IF(SUMPRODUCT((ISNUMBER(MATCH(IF(D20:H20<>"",D20:H20,0),IF(I20:K20<>"",I20:K20,999999),0)))*1)>0,"✅ 命中","❌")) | M20: =IF(L20="✅ 命中",IFERROR(INDEX(D20:H20,MATCH(1,ISNUMBER(MATCH(IF(D20:H20<>"",D20:H20,0),IF(I20:K20<>"",I20:K20,999999),0))*1,0)),""),"--") | Q20: 万能 | R20: =IFERROR(COUNTIFS(C5:C104,"万能",L5:L104,"✅ 命中")/COUNTIF(C5:C104,"万能"),0)
A21: 17 | L21: =IF(COUNTA(D21:H21)=0,"",IF(SUMPRODUCT((ISNUMBER(MATCH(IF(D21:H21<>"",D21:H21,0),IF(I21:K21<>"",I21:K21,999999),0)))*1)>0,"✅ 命中","❌")) | M21: =IF(L21="✅ 命中",IFERROR(INDEX(D21:H21,MATCH(1,ISNUMBER(MATCH(IF(D21:H21<>"",D21:H21,0),IF(I21:K21<>"",I21:K21,999999),0))*1,0)),""),"--") | Q21: 跑马 | R21: =IFERROR(COUNTIFS(C5:C104,"跑马",L5:L104,"✅ 命中")/COUNTIF(C5:C104,"跑马"),0)
A22: 18 | L22: =IF(COUNTA(D22:H22)=0,"",IF(SUMPRODUCT((ISNUMBER(MATCH(IF(D22:H22<>"",D22:H22,0),IF(I22:K22<>"",I22:K22,999999),0)))*1)>0,"✅ 命中","❌")) | M22: =IF(L22="✅ 命中",IFERROR(INDEX(D22:H22,MATCH(1,ISNUMBER(MATCH(IF(D22:H22<>"",D22:H22,0),IF(I22:K22<>"",I22:K22,999999),0))*1,0)),""),"--") | Q22: 多多 | R22: =IFERROR(COUNTIFS(C5:C104,"多多",L5:L104,"✅ 命中")/COUNTIF(C5:C104,"多多"),0)
A23: 19 | L23: =IF(COUNTA(D23:H23)=0,"",IF(SUMPRODUCT((ISNUMBER(MATCH(IF(D23:H23<>"",D23:H23,0),IF(I23:K23<>"",I23:K23,999999),0)))*1)>0,"✅ 命中","❌")) | M23: =IF(L23="✅ 命中",IFERROR(INDEX(D23:H23,MATCH(1,ISNUMBER(MATCH(IF(D23:H23<>"",D23:H23,0),IF(I23:K23<>"",I23:K23,999999),0))*1,0)),""),"--") | Q23: 新加坡 | R23: =IFERROR(COUNTIFS(C5:C104,"新加坡",L5:L104,"✅ 命中")/COUNTIF(C5:C104,"新加坡"),0)
A24: 20 | L24: =IF(COUNTA(D24:H24)=0,"",IF(SUMPRODUCT((ISNUMBER(MATCH(IF(D24:H24<>"",D24:H24,0),IF(I24:K24<>"",I24:K24,999999),0)))*1)>0,"✅ 命中","❌")) | M24: =IF(L24="✅ 命中",IFERROR(INDEX(D24:H24,MATCH(1,ISNUMBER(MATCH(IF(D24:H24<>"",D24:H24,0),IF(I24:K24<>"",I24:K24,999999),0))*1,0)),""),"--") | Q24: 豪龙 | R24: =IFERROR(COUNTIFS(C5:C104,"豪龙",L5:L104,"✅ 命中")/COUNTIF(C5:C104,"豪龙"),0)
A25: 21 | L25: =IF(COUNTA(D25:H25)=0,"",IF(SUMPRODUCT((ISNUMBER(MATCH(IF(D25:H25<>"",D25:H25,0),IF(I25:K25<>"",I25:K25,999999),0)))*1)>0,"✅ 命中","❌")) | M25: =IF(L25="✅ 命中",IFERROR(INDEX(D25:H25,MATCH(1,ISNUMBER(MATCH(IF(D25:H25<>"",D25:H25,0),IF(I25:K25<>"",I25:K25,999999),0))*1,0)),""),"--")
A26: 22 | L26: =IF(COUNTA(D26:H26)=0,"",IF(SUMPRODUCT((ISNUMBER(MATCH(IF(D26:H26<>"",D26:H26,0),IF(I26:K26<>"",I26:K26,999999),0)))*1)>0,"✅ 命中","❌")) | M26: =IF(L26="✅ 命中",IFERROR(INDEX(D26:H26,MATCH(1,ISNUMBER(MATCH(IF(D26:H26<>"",D26:H26,0),IF(I26:K26<>"",I26:K26,999999),0))*1,0)),""),"--")
A27: 23 | L27: =IF(COUNTA(D27:H27)=0,"",IF(SUMPRODUCT((ISNUMBER(MATCH(IF(D27:H27<>"",D27:H27,0),IF(I27:K27<>"",I27:K27,999999),0)))*1)>0,"✅ 命中","❌")) | M27: =IF(L27="✅ 命中",IFERROR(INDEX(D27:H27,MATCH(1,ISNUMBER(MATCH(IF(D27:H27<>"",D27:H27,0),IF(I27:K27<>"",I27:K27,999999),0))*1,0)),""),"--")
A28: 24 | L28: =IF(COUNTA(D28:H28)=0,"",IF(SUMPRODUCT((ISNUMBER(MATCH(IF(D28:H28<>"",D28:H28,0),IF(I28:K28<>"",I28:K28,999999),0)))*1)>0,"✅ 命中","❌")) | M28: =IF(L28="✅ 命中",IFERROR(INDEX(D28:H28,MATCH(1,ISNUMBER(MATCH(IF(D28:H28<>"",D28:H28,0),IF(I28:K28<>"",I28:K28,999999),0))*1,0)),""),"--")
A29: 25 | L29: =IF(COUNTA(D29:H29)=0,"",IF(SUMPRODUCT((ISNUMBER(MATCH(IF(D29:H29<>"",D29:H29,0),IF(I29:K29<>"",I29:K29,999999),0)))*1)>0,"✅ 命中","❌")) | M29: =IF(L29="✅ 命中",IFERROR(INDEX(D29:H29,MATCH(1,ISNUMBER(MATCH(IF(D29:H29<>"",D29:H29,0),IF(I29:K29<>"",I29:K29,999999),0))*1,0)),""),"--")
A30: 26 | L30: =IF(COUNTA(D30:H30)=0,"",IF(SUMPRODUCT((ISNUMBER(MATCH(IF(D30:H30<>"",D30:H30,0),IF(I30:K30<>"",I30:K30,999999),0)))*1)>0,"✅ 命中","❌")) | M30: =IF(L30="✅ 命中",IFERROR(INDEX(D30:H30,MATCH(1,ISNUMBER(MATCH(IF(D30:H30<>"",D30:H30,0),IF(I30:K30<>"",I30:K30,999999),0))*1,0)),""),"--")
A31: 27 | L31: =IF(COUNTA(D31:H31)=0,"",IF(SUMPRODUCT((ISNUMBER(MATCH(IF(D31:H31<>"",D31:H31,0),IF(I31:K31<>"",I31:K31,999999),0)))*1)>0,"✅ 命中","❌")) | M31: =IF(L31="✅ 命中",IFERROR(INDEX(D31:H31,MATCH(1,ISNUMBER(MATCH(IF(D31:H31<>"",D31:H31,0),IF(I31:K31<>"",I31:K31,999999),0))*1,0)),""),"--")
A32: 28 | L32: =IF(COUNTA(D32:H32)=0,"",IF(SUMPRODUCT((ISNUMBER(MATCH(IF(D32:H32<>"",D32:H32,0),IF(I32:K32<>"",I32:K32,999999),0)))*1)>0,"✅ 命中","❌")) | M32: =IF(L32="✅ 命中",IFERROR(INDEX(D32:H32,MATCH(1,ISNUMBER(MATCH(IF(D32:H32<>"",D32:H32,0),IF(I32:K32<>"",I32:K32,999999),0))*1,0)),""),"--")
A33: 29 | L33: =IF(COUNTA(D33:H33)=0,"",IF(SUMPRODUCT((ISNUMBER(MATCH(IF(D33:H33<>"",D33:H33,0),IF(I33:K33<>"",I33:K33,999999),0)))*1)>0,"✅ 命中","❌")) | M33: =IF(L33="✅ 命中",IFERROR(INDEX(D33:H33,MATCH(1,ISNUMBER(MATCH(IF(D33:H33<>"",D33:H33,0),IF(I33:K33<>"",I33:K33,999999),0))*1,0)),""),"--")
A34: 30 | L34: =IF(COUNTA(D34:H34)=0,"",IF(SUMPRODUCT((ISNUMBER(MATCH(IF(D34:H34<>"",D34:H34,0),IF(I34:K34<>"",I34:K34,999999),0)))*1)>0,"✅ 命中","❌")) | M34: =IF(L34="✅ 命中",IFERROR(INDEX(D34:H34,MATCH(1,ISNUMBER(MATCH(IF(D34:H34<>"",D34:H34,0),IF(I34:K34<>"",I34:K34,999999),0))*1,0)),""),"--")
A35: 31 | L35: =IF(COUNTA(D35:H35)=0,"",IF(SUMPRODUCT((ISNUMBER(MATCH(IF(D35:H35<>"",D35:H35,0),IF(I35:K35<>"",I35:K35,999999),0)))*1)>0,"✅ 命中","❌")) | M35: =IF(L35="✅ 命中",IFERROR(INDEX(D35:H35,MATCH(1,ISNUMBER(MATCH(IF(D35:H35<>"",D35:H35,0),IF(I35:K35<>"",I35:K35,999999),0))*1,0)),""),"--")
A36: 32 | L36: =IF(COUNTA(D36:H36)=0,"",IF(SUMPRODUCT((ISNUMBER(MATCH(IF(D36:H36<>"",D36:H36,0),IF(I36:K36<>"",I36:K36,999999),0)))*1)>0,"✅ 命中","❌")) | M36: =IF(L36="✅ 命中",IFERROR(INDEX(D36:H36,MATCH(1,ISNUMBER(MATCH(IF(D36:H36<>"",D36:H36,0),IF(I36:K36<>"",I36:K36,999999),0))*1,0)),""),"--")
... A104: 100 | L104: =IF(COUNTA(D104:H104)=0,"",IF(SUMPRODUCT((ISNUMBER(MATCH(IF(D104:H104<>"",D104:H104,0),IF(I104:K104<>"",I104:K104,999999),0)))*1)>0,"✅ 命中","❌")) | M104: =IF(L104="✅ 命中",IFERROR(INDEX(D104:H104,MATCH(1,ISNUMBER(MATCH(IF(D104:H104<>"",D104:H104,0),IF(I104:K104<>"",I104:K104,999999),0))*1,0)),""),"--")

Sheet 🔬 方法验证
A2: 🔬 方法验证表 — 哪个方法真的有效？
A3: 数据自动从「命中追踪」表读取 · 不需手动更新
A5: # | B5: 方法名称 | C5: 使用次数 | D5: 命中次数 | E5: 命中率 | F5: 评分 | G5: 建议
A6: 1 | B6: 数根链 | C6: =COUNTIF('📌 命中追踪'!N5:N104,"数根链") | D6: =COUNTIFS('📌 命中追踪'!N5:N104,"数根链",'📌 命中追踪'!L5:L104,"✅ 命中") | E6: =IFERROR(D6/C6,0) | F6: =IFERROR(IF(C6<3,"样本不足",IF(E6>=0.3,"★★★ 优秀",IF(E6>=0.2,"★★ 良好",IF(E6>=0.1,"★ 普通","✗ 效果差")))),"—") | G6: =IFERROR(IF(C6<3,"需更多数据",IF(E6>=0.3,"继续使用",IF(E6>=0.15,"保持观察",IF(E6<0.08,"考虑停用","维持现状")))),"—")
A7: 2 | B7: 配对分析 | C7: =COUNTIF('📌 命中追踪'!N5:N104,"配对分析") | D7: =COUNTIFS('📌 命中追踪'!N5:N104,"配对分析",'📌 命中追踪'!L5:L104,"✅ 命中") | E7: =IFERROR(D7/C7,0) | F7: =IFERROR(IF(C7<3,"样本不足",IF(E7>=0.3,"★★★ 优秀",IF(E7>=0.2,"★★ 良好",IF(E7>=0.1,"★ 普通","✗ 效果差")))),"—") | G7: =IFERROR(IF(C7<3,"需更多数据",IF(E7>=0.3,"继续使用",IF(E7>=0.15,"保持观察",IF(E7<0.08,"考虑停用","维持现状")))),"—")
A8: 3 | B8: 冷热库 | C8: =COUNTIF('📌 命中追踪'!N5:N104,"冷热库") | D8: =COUNTIFS('📌 命中追踪'!N5:N104,"冷热库",'📌 命中追踪'!L5:L104,"✅ 命中") | E8: =IFERROR(D8/C8,0) | F8: =IFERROR(IF(C8<3,"样本不足",IF(E8>=0.3,"★★★ 优秀",IF(E8>=0.2,"★★ 良好",IF(E8>=0.1,"★ 普通","✗ 效果差")))),"—") | G8: =IFERROR(IF(C8<3,"需更多数据",IF(E8>=0.3,"继续使用",IF(E8>=0.15,"保持观察",IF(E8<0.08,"考虑停用","维持现状")))),"—")
A9: 4 | B9: 四步向导 | C9: =COUNTIF('📌 命中追踪'!N5:N104,"四步向导") | D9: =COUNTIFS('📌 命中追踪'!N5:N104,"四步向导",'📌 命中追踪'!L5:L104,"✅ 命中") | E9: =IFERROR(D9/C9,0) | F9: =IFERROR(IF(C9<3,"样本不足",IF(E9>=0.3,"★★★ 优秀",IF(E9>=0.2,"★★ 良好",IF(E9>=0.1,"★ 普通","✗ 效果差")))),"—") | G9: =IFERROR(IF(C9<3,"需更多数据",IF(E9>=0.3,"继续使用",IF(E9>=0.15,"保持观察",IF(E9<0.08,"考虑停用","维持现状")))),"—")
A10: 5 | B10: 工作台 | C10: =COUNTIF('📌 命中追踪'!N5:N104,"工作台") | D10: =COUNTIFS('📌 命中追踪'!N5:N104,"工作台",'📌 命中追踪'!L5:L104,"✅ 命中") | E10: =IFERROR(D10/C10,0) | F10: =IFERROR(IF(C10<3,"样本不足",IF(E10>=0.3,"★★★ 优秀",IF(E10>=0.2,"★★ 良好",IF(E10>=0.1,"★ 普通","✗ 效果差")))),"—") | G10: =IFERROR(IF(C10<3,"需更多数据",IF(E10>=0.3,"继续使用",IF(E10>=0.15,"保持观察",IF(E10<0.08,"考虑停用","维持现状")))),"—")
A11: 6 | B11: 点数区间 | C11: =COUNTIF('📌 命中追踪'!N5:N104,"点数区间") | D11: =COUNTIFS('📌 命中追踪'!N5:N104,"点数区间",'📌 命中追踪'!L5:L104,"✅ 命中") | E11: =IFERROR(D11/C11,0) | F11: =IFERROR(IF(C11<3,"样本不足",IF(E11>=0.3,"★★★ 优秀",IF(E11>=0.2,"★★ 良好",IF(E11>=0.1,"★ 普通","✗ 效果差")))),"—") | G11: =IFERROR(IF(C11<3,"需更多数据",IF(E11>=0.3,"继续使用",IF(E11>=0.15,"保持观察",IF(E11<0.08,"考虑停用","维持现状")))),"—")
A12: 7 | B12: 条件筛选 | C12: =COUNTIF('📌 命中追踪'!N5:N104,"条件筛选") | D12: =COUNTIFS('📌 命中追踪'!N5:N104,"条件筛选",'📌 命中追踪'!L5:L104,"✅ 命中") | E12: =IFERROR(D12/C12,0) | F12: =IFERROR(IF(C12<3,"样本不足",IF(E12>=0.3,"★★★ 优秀",IF(E12>=0.2,"★★ 良好",IF(E12>=0.1,"★ 普通","✗ 效果差")))),"—") | G12: =IFERROR(IF(C12<3,"需更多数据",IF(E12>=0.3,"继续使用",IF(E12>=0.15,"保持观察",IF(E12<0.08,"考虑停用","维持现状")))),"—")
A13: 8 | B13: 人工判断 | C13: =COUNTIF('📌 命中追踪'!N5:N104,"人工判断") | D13: =COUNTIFS('📌 命中追踪'!N5:N104,"人工判断",'📌 命中追踪'!L5:L104,"✅ 命中") | E13: =IFERROR(D13/C13,0) | F13: =IFERROR(IF(C13<3,"样本不足",IF(E13>=0.3,"★★★ 优秀",IF(E13>=0.2,"★★ 良好",IF(E13>=0.1,"★ 普通","✗ 效果差")))),"—") | G13: =IFERROR(IF(C13<3,"需更多数据",IF(E13>=0.3,"继续使用",IF(E13>=0.15,"保持观察",IF(E13<0.08,"考虑停用","维持现状")))),"—")
A14: 9 | B14: 其他 | C14: =COUNTIF('📌 命中追踪'!N5:N104,"其他") | D14: =COUNTIFS('📌 命中追踪'!N5:N104,"其他",'📌 命中追踪'!L5:L104,"✅ 命中") | E14: =IFERROR(D14/C14,0) | F14: =IFERROR(IF(C14<3,"样本不足",IF(E14>=0.3,"★★★ 优秀",IF(E14>=0.2,"★★ 良好",IF(E14>=0.1,"★ 普通","✗ 效果差")))),"—") | G14: =IFERROR(IF(C14<3,"需更多数据",IF(E14>=0.3,"继续使用",IF(E14>=0.15,"保持观察",IF(E14<0.08,"考虑停用","维持现状")))),"—")
B15: 全部方法合计 | C15: =SUM(C6:C14) | D15: =SUM(D6:D14) | E15: =IFERROR(D15/C15,0)
A17: 🏪 各市场命中表现
A18: # | B18: 市场 | C18: 使用次数 | D18: 命中次数 | E18: 命中率 | F18: 最近命中 | G18: 评分
A19: 1 | B19: 万能 | C19: =COUNTIF('📌 命中追踪'!C5:C104,"万能") | D19: =COUNTIFS('📌 命中追踪'!C5:C104,"万能",'📌 命中追踪'!L5:L104,"✅ 命中") | E19: =IFERROR(D19/C19,0) | F19: =IFERROR(_xlfn.MAXIFS('📌 命中追踪'!B5:B104,'📌 命中追踪'!C5:C104,"万能",'📌 命中追踪'!L5:L104,"✅ 命中"),"—") | G19: =IFERROR(IF(C19<3,"样本不足",IF(E19>=0.3,"★★★",IF(E19>=0.2,"★★",IF(E19>=0.1,"★","✗")))),"—")
A20: 2 | B20: 跑马 | C20: =COUNTIF('📌 命中追踪'!C5:C104,"跑马") | D20: =COUNTIFS('📌 命中追踪'!C5:C104,"跑马",'📌 命中追踪'!L5:L104,"✅ 命中") | E20: =IFERROR(D20/C20,0) | F20: =IFERROR(_xlfn.MAXIFS('📌 命中追踪'!B5:B104,'📌 命中追踪'!C5:C104,"跑马",'📌 命中追踪'!L5:L104,"✅ 命中"),"—") | G20: =IFERROR(IF(C20<3,"样本不足",IF(E20>=0.3,"★★★",IF(E20>=0.2,"★★",IF(E20>=0.1,"★","✗")))),"—")
A21: 3 | B21: 多多 | C21: =COUNTIF('📌 命中追踪'!C5:C104,"多多") | D21: =COUNTIFS('📌 命中追踪'!C5:C104,"多多",'📌 命中追踪'!L5:L104,"✅ 命中") | E21: =IFERROR(D21/C21,0) | F21: =IFERROR(_xlfn.MAXIFS('📌 命中追踪'!B5:B104,'📌 命中追踪'!C5:C104,"多多",'📌 命中追踪'!L5:L104,"✅ 命中"),"—") | G21: =IFERROR(IF(C21<3,"样本不足",IF(E21>=0.3,"★★★",IF(E21>=0.2,"★★",IF(E21>=0.1,"★","✗")))),"—")
A22: 4 | B22: 新加坡 | C22: =COUNTIF('📌 命中追踪'!C5:C104,"新加坡") | D22: =COUNTIFS('📌 命中追踪'!C5:C104,"新加坡",'📌 命中追踪'!L5:L104,"✅ 命中") | E22: =IFERROR(D22/C22,0) | F22: =IFERROR(_xlfn.MAXIFS('📌 命中追踪'!B5:B104,'📌 命中追踪'!C5:C104,"新加坡",'📌 命中追踪'!L5:L104,"✅ 命中"),"—") | G22: =IFERROR(IF(C22<3,"样本不足",IF(E22>=0.3,"★★★",IF(E22>=0.2,"★★",IF(E22>=0.1,"★","✗")))),"—")
A23: 5 | B23: 豪龙 | C23: =COUNTIF('📌 命中追踪'!C5:C104,"豪龙") | D23: =COUNTIFS('📌 命中追踪'!C5:C104,"豪龙",'📌 命中追踪'!L5:L104,"✅ 命中") | E23: =IFERROR(D23/C23,0) | F23: =IFERROR(_xlfn.MAXIFS('📌 命中追踪'!B5:B104,'📌 命中追踪'!C5:C104,"豪龙",'📌 命中追踪'!L5:L104,"✅ 命中"),"—") | G23: =IFERROR(IF(C23<3,"样本不足",IF(E23>=0.3,"★★★",IF(E23>=0.2,"★★",IF(E23>=0.1,"★","✗")))),"—")

Sheet 📊 月度总结
A2: 📊 月度总结 — 每月命中率追踪
A3: 请在B列手动填入月份（格式：2026-01），其余列自动计算
A5: # | B5: 月份 | C5: 总期数 | D5: 有记录 | E5: 命中次数 | F5: 命中率 | G5: 最佳方法 | H5: 趋势
A6: 1 | C6: =IF(B6="","",SUMPRODUCT((TEXT('📌 命中追踪'!B5:B104,"YYYY-MM")=TEXT(B6,"YYYY-MM"))*1)) | D6: =IF(B6="","",SUMPRODUCT((TEXT('📌 命中追踪'!B5:B104,"YYYY-MM")=TEXT(B6,"YYYY-MM"))*('📌 命中追踪'!L5:L104<>""))) | E6: =IF(B6="","",SUMPRODUCT((TEXT('📌 命中追踪'!B5:B104,"YYYY-MM")=TEXT(B6,"YYYY-MM"))*('📌 命中追踪'!L5:L104="✅ 命中"))) | F6: =IFERROR(E6/D6,"") | G6: =IF(B6="","",LET(mon,TEXT(B6,"YYYY-MM"),names,{"数根链","配对分析","冷热库","四步向导","工作台","点数区间","条件筛选","人工判断","其他"},base,(TEXT('📌 命中追踪'!B:B04,"YYYY-MM")=mon)*('📌 命中追踪'!L:L04="✅ 命中"),mtx,--( '📌 命中追踪'!N:N04=names),counts,MMULT(TRANSPOSE(base*1),mtx),IF(MAX(counts)=0,"—",INDEX(names,MATCH(MAX(counts),counts,0))))) | H6: =IF(OR(B6="",F6=""),"",IF(ROW()=6,"—",IF(F5="","—",IF(F6>F5,"📈 上升",IF(F6<F5,"📉 下降","➡ 持平")))))
A7: 2 | C7: =IF(B7="","",SUMPRODUCT((TEXT('📌 命中追踪'!B5:B104,"YYYY-MM")=TEXT(B7,"YYYY-MM"))*1)) | D7: =IF(B7="","",SUMPRODUCT((TEXT('📌 命中追踪'!B5:B104,"YYYY-MM")=TEXT(B7,"YYYY-MM"))*('📌 命中追踪'!L5:L104<>""))) | E7: =IF(B7="","",SUMPRODUCT((TEXT('📌 命中追踪'!B5:B104,"YYYY-MM")=TEXT(B7,"YYYY-MM"))*('📌 命中追踪'!L5:L104="✅ 命中"))) | F7: =IFERROR(E7/D7,"") | G7: =IF(B7="","",LET(mon,TEXT(B7,"YYYY-MM"),names,{"数根链","配对分析","冷热库","四步向导","工作台","点数区间","条件筛选","人工判断","其他"},base,(TEXT('📌 命中追踪'!B:B04,"YYYY-MM")=mon)*('📌 命中追踪'!L:L04="✅ 命中"),mtx,--( '📌 命中追踪'!N:N04=names),counts,MMULT(TRANSPOSE(base*1),mtx),IF(MAX(counts)=0,"—",INDEX(names,MATCH(MAX(counts),counts,0))))) | H7: =IF(OR(B7="",F7=""),"",IF(ROW()=6,"—",IF(F6="","—",IF(F7>F6,"📈 上升",IF(F7<F6,"📉 下降","➡ 持平")))))
A8: 3 | C8: =IF(B8="","",SUMPRODUCT((TEXT('📌 命中追踪'!B5:B104,"YYYY-MM")=TEXT(B8,"YYYY-MM"))*1)) | D8: =IF(B8="","",SUMPRODUCT((TEXT('📌 命中追踪'!B5:B104,"YYYY-MM")=TEXT(B8,"YYYY-MM"))*('📌 命中追踪'!L5:L104<>""))) | E8: =IF(B8="","",SUMPRODUCT((TEXT('📌 命中追踪'!B5:B104,"YYYY-MM")=TEXT(B8,"YYYY-MM"))*('📌 命中追踪'!L5:L104="✅ 命中"))) | F8: =IFERROR(E8/D8,"") | G8: =IF(B8="","",LET(mon,TEXT(B8,"YYYY-MM"),names,{"数根链","配对分析","冷热库","四步向导","工作台","点数区间","条件筛选","人工判断","其他"},base,(TEXT('📌 命中追踪'!B:B04,"YYYY-MM")=mon)*('📌 命中追踪'!L:L04="✅ 命中"),mtx,--( '📌 命中追踪'!N:N04=names),counts,MMULT(TRANSPOSE(base*1),mtx),IF(MAX(counts)=0,"—",INDEX(names,MATCH(MAX(counts),counts,0))))) | H8: =IF(OR(B8="",F8=""),"",IF(ROW()=6,"—",IF(F7="","—",IF(F8>F7,"📈 上升",IF(F8<F7,"📉 下降","➡ 持平")))))
A9: 4 | C9: =IF(B9="","",SUMPRODUCT((TEXT('📌 命中追踪'!B5:B104,"YYYY-MM")=TEXT(B9,"YYYY-MM"))*1)) | D9: =IF(B9="","",SUMPRODUCT((TEXT('📌 命中追踪'!B5:B104,"YYYY-MM")=TEXT(B9,"YYYY-MM"))*('📌 命中追踪'!L5:L104<>""))) | E9: =IF(B9="","",SUMPRODUCT((TEXT('📌 命中追踪'!B5:B104,"YYYY-MM")=TEXT(B9,"YYYY-MM"))*('📌 命中追踪'!L5:L104="✅ 命中"))) | F9: =IFERROR(E9/D9,"") | G9: =IF(B9="","",LET(mon,TEXT(B9,"YYYY-MM"),names,{"数根链","配对分析","冷热库","四步向导","工作台","点数区间","条件筛选","人工判断","其他"},base,(TEXT('📌 命中追踪'!B:B04,"YYYY-MM")=mon)*('📌 命中追踪'!L:L04="✅ 命中"),mtx,--( '📌 命中追踪'!N:N04=names),counts,MMULT(TRANSPOSE(base*1),mtx),IF(MAX(counts)=0,"—",INDEX(names,MATCH(MAX(counts),counts,0))))) | H9: =IF(OR(B9="",F9=""),"",IF(ROW()=6,"—",IF(F8="","—",IF(F9>F8,"📈 上升",IF(F9<F8,"📉 下降","➡ 持平")))))
A10: 5 | C10: =IF(B10="","",SUMPRODUCT((TEXT('📌 命中追踪'!B5:B104,"YYYY-MM")=TEXT(B10,"YYYY-MM"))*1)) | D10: =IF(B10="","",SUMPRODUCT((TEXT('📌 命中追踪'!B5:B104,"YYYY-MM")=TEXT(B10,"YYYY-MM"))*('📌 命中追踪'!L5:L104<>""))) | E10: =IF(B10="","",SUMPRODUCT((TEXT('📌 命中追踪'!B5:B104,"YYYY-MM")=TEXT(B10,"YYYY-MM"))*('📌 命中追踪'!L5:L104="✅ 命中"))) | F10: =IFERROR(E10/D10,"") | G10: =IF(B10="","",LET(mon,TEXT(B10,"YYYY-MM"),names,{"数根链","配对分析","冷热库","四步向导","工作台","点数区间","条件筛选","人工判断","其他"},base,(TEXT('📌 命中追踪'!B:B04,"YYYY-MM")=mon)*('📌 命中追踪'!L:L04="✅ 命中"),mtx,--( '📌 命中追踪'!N:N04=names),counts,MMULT(TRANSPOSE(base*1),mtx),IF(MAX(counts)=0,"—",INDEX(names,MATCH(MAX(counts),counts,0))))) | H10: =IF(OR(B10="",F10=""),"",IF(ROW()=6,"—",IF(F9="","—",IF(F10>F9,"📈 上升",IF(F10<F9,"📉 下降","➡ 持平")))))
A11: 6 | C11: =IF(B11="","",SUMPRODUCT((TEXT('📌 命中追踪'!B5:B104,"YYYY-MM")=TEXT(B11,"YYYY-MM"))*1)) | D11: =IF(B11="","",SUMPRODUCT((TEXT('📌 命中追踪'!B5:B104,"YYYY-MM")=TEXT(B11,"YYYY-MM"))*('📌 命中追踪'!L5:L104<>""))) | E11: =IF(B11="","",SUMPRODUCT((TEXT('📌 命中追踪'!B5:B104,"YYYY-MM")=TEXT(B11,"YYYY-MM"))*('📌 命中追踪'!L5:L104="✅ 命中"))) | F11: =IFERROR(E11/D11,"") | G11: =IF(B11="","",LET(mon,TEXT(B11,"YYYY-MM"),names,{"数根链","配对分析","冷热库","四步向导","工作台","点数区间","条件筛选","人工判断","其他"},base,(TEXT('📌 命中追踪'!B:B04,"YYYY-MM")=mon)*('📌 命中追踪'!L:L04="✅ 命中"),mtx,--( '📌 命中追踪'!N:N04=names),counts,MMULT(TRANSPOSE(base*1),mtx),IF(MAX(counts)=0,"—",INDEX(names,MATCH(MAX(counts),counts,0))))) | H11: =IF(OR(B11="",F11=""),"",IF(ROW()=6,"—",IF(F10="","—",IF(F11>F10,"📈 上升",IF(F11<F10,"📉 下降","➡ 持平")))))
A12: 7 | C12: =IF(B12="","",SUMPRODUCT((TEXT('📌 命中追踪'!B5:B104,"YYYY-MM")=TEXT(B12,"YYYY-MM"))*1)) | D12: =IF(B12="","",SUMPRODUCT((TEXT('📌 命中追踪'!B5:B104,"YYYY-MM")=TEXT(B12,"YYYY-MM"))*('📌 命中追踪'!L5:L104<>""))) | E12: =IF(B12="","",SUMPRODUCT((TEXT('📌 命中追踪'!B5:B104,"YYYY-MM")=TEXT(B12,"YYYY-MM"))*('📌 命中追踪'!L5:L104="✅ 命中"))) | F12: =IFERROR(E12/D12,"") | G12: =IF(B12="","",LET(mon,TEXT(B12,"YYYY-MM"),names,{"数根链","配对分析","冷热库","四步向导","工作台","点数区间","条件筛选","人工判断","其他"},base,(TEXT('📌 命中追踪'!B:B04,"YYYY-MM")=mon)*('📌 命中追踪'!L:L04="✅ 命中"),mtx,--( '📌 命中追踪'!N:N04=names),counts,MMULT(TRANSPOSE(base*1),mtx),IF(MAX(counts)=0,"—",INDEX(names,MATCH(MAX(counts),counts,0))))) | H12: =IF(OR(B12="",F12=""),"",IF(ROW()=6,"—",IF(F11="","—",IF(F12>F11,"📈 上升",IF(F12<F11,"📉 下降","➡ 持平")))))
A13: 8 | C13: =IF(B13="","",SUMPRODUCT((TEXT('📌 命中追踪'!B5:B104,"YYYY-MM")=TEXT(B13,"YYYY-MM"))*1)) | D13: =IF(B13="","",SUMPRODUCT((TEXT('📌 命中追踪'!B5:B104,"YYYY-MM")=TEXT(B13,"YYYY-MM"))*('📌 命中追踪'!L5:L104<>""))) | E13: =IF(B13="","",SUMPRODUCT((TEXT('📌 命中追踪'!B5:B104,"YYYY-MM")=TEXT(B13,"YYYY-MM"))*('📌 命中追踪'!L5:L104="✅ 命中"))) | F13: =IFERROR(E13/D13,"") | G13: =IF(B13="","",LET(mon,TEXT(B13,"YYYY-MM"),names,{"数根链","配对分析","冷热库","四步向导","工作台","点数区间","条件筛选","人工判断","其他"},base,(TEXT('📌 命中追踪'!B:B04,"YYYY-MM")=mon)*('📌 命中追踪'!L:L04="✅ 命中"),mtx,--( '📌 命中追踪'!N:N04=names),counts,MMULT(TRANSPOSE(base*1),mtx),IF(MAX(counts)=0,"—",INDEX(names,MATCH(MAX(counts),counts,0))))) | H13: =IF(OR(B13="",F13=""),"",IF(ROW()=6,"—",IF(F12="","—",IF(F13>F12,"📈 上升",IF(F13<F12,"📉 下降","➡ 持平")))))
A14: 9 | C14: =IF(B14="","",SUMPRODUCT((TEXT('📌 命中追踪'!B5:B104,"YYYY-MM")=TEXT(B14,"YYYY-MM"))*1)) | D14: =IF(B14="","",SUMPRODUCT((TEXT('📌 命中追踪'!B5:B104,"YYYY-MM")=TEXT(B14,"YYYY-MM"))*('📌 命中追踪'!L5:L104<>""))) | E14: =IF(B14="","",SUMPRODUCT((TEXT('📌 命中追踪'!B5:B104,"YYYY-MM")=TEXT(B14,"YYYY-MM"))*('📌 命中追踪'!L5:L104="✅ 命中"))) | F14: =IFERROR(E14/D14,"") | G14: =IF(B14="","",LET(mon,TEXT(B14,"YYYY-MM"),names,{"数根链","配对分析","冷热库","四步向导","工作台","点数区间","条件筛选","人工判断","其他"},base,(TEXT('📌 命中追踪'!B:B04,"YYYY-MM")=mon)*('📌 命中追踪'!L:L04="✅ 命中"),mtx,--( '📌 命中追踪'!N:N04=names),counts,MMULT(TRANSPOSE(base*1),mtx),IF(MAX(counts)=0,"—",INDEX(names,MATCH(MAX(counts),counts,0))))) | H14: =IF(OR(B14="",F14=""),"",IF(ROW()=6,"—",IF(F13="","—",IF(F14>F13,"📈 上升",IF(F14<F13,"📉 下降","➡ 持平")))))
A15: 10 | C15: =IF(B15="","",SUMPRODUCT((TEXT('📌 命中追踪'!B5:B104,"YYYY-MM")=TEXT(B15,"YYYY-MM"))*1)) | D15: =IF(B15="","",SUMPRODUCT((TEXT('📌 命中追踪'!B5:B104,"YYYY-MM")=TEXT(B15,"YYYY-MM"))*('📌 命中追踪'!L5:L104<>""))) | E15: =IF(B15="","",SUMPRODUCT((TEXT('📌 命中追踪'!B5:B104,"YYYY-MM")=TEXT(B15,"YYYY-MM"))*('📌 命中追踪'!L5:L104="✅ 命中"))) | F15: =IFERROR(E15/D15,"") | G15: =IF(B15="","",LET(mon,TEXT(B15,"YYYY-MM"),names,{"数根链","配对分析","冷热库","四步向导","工作台","点数区间","条件筛选","人工判断","其他"},base,(TEXT('📌 命中追踪'!B:B04,"YYYY-MM")=mon)*('📌 命中追踪'!L:L04="✅ 命中"),mtx,--( '📌 命中追踪'!N:N04=names),counts,MMULT(TRANSPOSE(base*1),mtx),IF(MAX(counts)=0,"—",INDEX(names,MATCH(MAX(counts),counts,0))))) | H15: =IF(OR(B15="",F15=""),"",IF(ROW()=6,"—",IF(F14="","—",IF(F15>F14,"📈 上升",IF(F15<F14,"📉 下降","➡ 持平")))))
A16: 11 | C16: =IF(B16="","",SUMPRODUCT((TEXT('📌 命中追踪'!B5:B104,"YYYY-MM")=TEXT(B16,"YYYY-MM"))*1)) | D16: =IF(B16="","",SUMPRODUCT((TEXT('📌 命中追踪'!B5:B104,"YYYY-MM")=TEXT(B16,"YYYY-MM"))*('📌 命中追踪'!L5:L104<>""))) | E16: =IF(B16="","",SUMPRODUCT((TEXT('📌 命中追踪'!B5:B104,"YYYY-MM")=TEXT(B16,"YYYY-MM"))*('📌 命中追踪'!L5:L104="✅ 命中"))) | F16: =IFERROR(E16/D16,"") | G16: =IF(B16="","",LET(mon,TEXT(B16,"YYYY-MM"),names,{"数根链","配对分析","冷热库","四步向导","工作台","点数区间","条件筛选","人工判断","其他"},base,(TEXT('📌 命中追踪'!B:B04,"YYYY-MM")=mon)*('📌 命中追踪'!L:L04="✅ 命中"),mtx,--( '📌 命中追踪'!N:N04=names),counts,MMULT(TRANSPOSE(base*1),mtx),IF(MAX(counts)=0,"—",INDEX(names,MATCH(MAX(counts),counts,0))))) | H16: =IF(OR(B16="",F16=""),"",IF(ROW()=6,"—",IF(F15="","—",IF(F16>F15,"📈 上升",IF(F16<F15,"📉 下降","➡ 持平")))))
A17: 12 | C17: =IF(B17="","",SUMPRODUCT((TEXT('📌 命中追踪'!B5:B104,"YYYY-MM")=TEXT(B17,"YYYY-MM"))*1)) | D17: =IF(B17="","",SUMPRODUCT((TEXT('📌 命中追踪'!B5:B104,"YYYY-MM")=TEXT(B17,"YYYY-MM"))*('📌 命中追踪'!L5:L104<>""))) | E17: =IF(B17="","",SUMPRODUCT((TEXT('📌 命中追踪'!B5:B104,"YYYY-MM")=TEXT(B17,"YYYY-MM"))*('📌 命中追踪'!L5:L104="✅ 命中"))) | F17: =IFERROR(E17/D17,"") | G17: =IF(B17="","",LET(mon,TEXT(B17,"YYYY-MM"),names,{"数根链","配对分析","冷热库","四步向导","工作台","点数区间","条件筛选","人工判断","其他"},base,(TEXT('📌 命中追踪'!B:B04,"YYYY-MM")=mon)*('📌 命中追踪'!L:L04="✅ 命中"),mtx,--( '📌 命中追踪'!N:N04=names),counts,MMULT(TRANSPOSE(base*1),mtx),IF(MAX(counts)=0,"—",INDEX(names,MATCH(MAX(counts),counts,0))))) | H17: =IF(OR(B17="",F17=""),"",IF(ROW()=6,"—",IF(F16="","—",IF(F17>F16,"📈 上升",IF(F17<F16,"📉 下降","➡ 持平")))))
A18: 13 | C18: =IF(B18="","",SUMPRODUCT((TEXT('📌 命中追踪'!B5:B104,"YYYY-MM")=TEXT(B18,"YYYY-MM"))*1)) | D18: =IF(B18="","",SUMPRODUCT((TEXT('📌 命中追踪'!B5:B104,"YYYY-MM")=TEXT(B18,"YYYY-MM"))*('📌 命中追踪'!L5:L104<>""))) | E18: =IF(B18="","",SUMPRODUCT((TEXT('📌 命中追踪'!B5:B104,"YYYY-MM")=TEXT(B18,"YYYY-MM"))*('📌 命中追踪'!L5:L104="✅ 命中"))) | F18: =IFERROR(E18/D18,"") | G18: =IF(B18="","",LET(mon,TEXT(B18,"YYYY-MM"),names,{"数根链","配对分析","冷热库","四步向导","工作台","点数区间","条件筛选","人工判断","其他"},base,(TEXT('📌 命中追踪'!B:B04,"YYYY-MM")=mon)*('📌 命中追踪'!L:L04="✅ 命中"),mtx,--( '📌 命中追踪'!N:N04=names),counts,MMULT(TRANSPOSE(base*1),mtx),IF(MAX(counts)=0,"—",INDEX(names,MATCH(MAX(counts),counts,0))))) | H18: =IF(OR(B18="",F18=""),"",IF(ROW()=6,"—",IF(F17="","—",IF(F18>F17,"📈 上升",IF(F18<F17,"📉 下降","➡ 持平")))))
A19: 14 | C19: =IF(B19="","",SUMPRODUCT((TEXT('📌 命中追踪'!B5:B104,"YYYY-MM")=TEXT(B19,"YYYY-MM"))*1)) | D19: =IF(B19="","",SUMPRODUCT((TEXT('📌 命中追踪'!B5:B104,"YYYY-MM")=TEXT(B19,"YYYY-MM"))*('📌 命中追踪'!L5:L104<>""))) | E19: =IF(B19="","",SUMPRODUCT((TEXT('📌 命中追踪'!B5:B104,"YYYY-MM")=TEXT(B19,"YYYY-MM"))*('📌 命中追踪'!L5:L104="✅ 命中"))) | F19: =IFERROR(E19/D19,"") | G19: =IF(B19="","",LET(mon,TEXT(B19,"YYYY-MM"),names,{"数根链","配对分析","冷热库","四步向导","工作台","点数区间","条件筛选","人工判断","其他"},base,(TEXT('📌 命中追踪'!B:B04,"YYYY-MM")=mon)*('📌 命中追踪'!L:L04="✅ 命中"),mtx,--( '📌 命中追踪'!N:N04=names),counts,MMULT(TRANSPOSE(base*1),mtx),IF(MAX(counts)=0,"—",INDEX(names,MATCH(MAX(counts),counts,0))))) | H19: =IF(OR(B19="",F19=""),"",IF(ROW()=6,"—",IF(F18="","—",IF(F19>F18,"📈 上升",IF(F19<F18,"📉 下降","➡ 持平")))))
A20: 15 | C20: =IF(B20="","",SUMPRODUCT((TEXT('📌 命中追踪'!B5:B104,"YYYY-MM")=TEXT(B20,"YYYY-MM"))*1)) | D20: =IF(B20="","",SUMPRODUCT((TEXT('📌 命中追踪'!B5:B104,"YYYY-MM")=TEXT(B20,"YYYY-MM"))*('📌 命中追踪'!L5:L104<>""))) | E20: =IF(B20="","",SUMPRODUCT((TEXT('📌 命中追踪'!B5:B104,"YYYY-MM")=TEXT(B20,"YYYY-MM"))*('📌 命中追踪'!L5:L104="✅ 命中"))) | F20: =IFERROR(E20/D20,"") | G20: =IF(B20="","",LET(mon,TEXT(B20,"YYYY-MM"),names,{"数根链","配对分析","冷热库","四步向导","工作台","点数区间","条件筛选","人工判断","其他"},base,(TEXT('📌 命中追踪'!B:B04,"YYYY-MM")=mon)*('📌 命中追踪'!L:L04="✅ 命中"),mtx,--( '📌 命中追踪'!N:N04=names),counts,MMULT(TRANSPOSE(base*1),mtx),IF(MAX(counts)=0,"—",INDEX(names,MATCH(MAX(counts),counts,0))))) | H20: =IF(OR(B20="",F20=""),"",IF(ROW()=6,"—",IF(F19="","—",IF(F20>F19,"📈 上升",IF(F20<F19,"📉 下降","➡ 持平")))))
A21: 16 | C21: =IF(B21="","",SUMPRODUCT((TEXT('📌 命中追踪'!B5:B104,"YYYY-MM")=TEXT(B21,"YYYY-MM"))*1)) | D21: =IF(B21="","",SUMPRODUCT((TEXT('📌 命中追踪'!B5:B104,"YYYY-MM")=TEXT(B21,"YYYY-MM"))*('📌 命中追踪'!L5:L104<>""))) | E21: =IF(B21="","",SUMPRODUCT((TEXT('📌 命中追踪'!B5:B104,"YYYY-MM")=TEXT(B21,"YYYY-MM"))*('📌 命中追踪'!L5:L104="✅ 命中"))) | F21: =IFERROR(E21/D21,"") | G21: =IF(B21="","",LET(mon,TEXT(B21,"YYYY-MM"),names,{"数根链","配对分析","冷热库","四步向导","工作台","点数区间","条件筛选","人工判断","其他"},base,(TEXT('📌 命中追踪'!B:B04,"YYYY-MM")=mon)*('📌 命中追踪'!L:L04="✅ 命中"),mtx,--( '📌 命中追踪'!N:N04=names),counts,MMULT(TRANSPOSE(base*1),mtx),IF(MAX(counts)=0,"—",INDEX(names,MATCH(MAX(counts),counts,0))))) | H21: =IF(OR(B21="",F21=""),"",IF(ROW()=6,"—",IF(F20="","—",IF(F21>F20,"📈 上升",IF(F21<F20,"📉 下降","➡ 持平")))))
A22: 17 | C22: =IF(B22="","",SUMPRODUCT((TEXT('📌 命中追踪'!B5:B104,"YYYY-MM")=TEXT(B22,"YYYY-MM"))*1)) | D22: =IF(B22="","",SUMPRODUCT((TEXT('📌 命中追踪'!B5:B104,"YYYY-MM")=TEXT(B22,"YYYY-MM"))*('📌 命中追踪'!L5:L104<>""))) | E22: =IF(B22="","",SUMPRODUCT((TEXT('📌 命中追踪'!B5:B104,"YYYY-MM")=TEXT(B22,"YYYY-MM"))*('📌 命中追踪'!L5:L104="✅ 命中"))) | F22: =IFERROR(E22/D22,"") | G22: =IF(B22="","",LET(mon,TEXT(B22,"YYYY-MM"),names,{"数根链","配对分析","冷热库","四步向导","工作台","点数区间","条件筛选","人工判断","其他"},base,(TEXT('📌 命中追踪'!B:B04,"YYYY-MM")=mon)*('📌 命中追踪'!L:L04="✅ 命中"),mtx,--( '📌 命中追踪'!N:N04=names),counts,MMULT(TRANSPOSE(base*1),mtx),IF(MAX(counts)=0,"—",INDEX(names,MATCH(MAX(counts),counts,0))))) | H22: =IF(OR(B22="",F22=""),"",IF(ROW()=6,"—",IF(F21="","—",IF(F22>F21,"📈 上升",IF(F22<F21,"📉 下降","➡ 持平")))))
A23: 18 | C23: =IF(B23="","",SUMPRODUCT((TEXT('📌 命中追踪'!B5:B104,"YYYY-MM")=TEXT(B23,"YYYY-MM"))*1)) | D23: =IF(B23="","",SUMPRODUCT((TEXT('📌 命中追踪'!B5:B104,"YYYY-MM")=TEXT(B23,"YYYY-MM"))*('📌 命中追踪'!L5:L104<>""))) | E23: =IF(B23="","",SUMPRODUCT((TEXT('📌 命中追踪'!B5:B104,"YYYY-MM")=TEXT(B23,"YYYY-MM"))*('📌 命中追踪'!L5:L104="✅ 命中"))) | F23: =IFERROR(E23/D23,"") | G23: =IF(B23="","",LET(mon,TEXT(B23,"YYYY-MM"),names,{"数根链","配对分析","冷热库","四步向导","工作台","点数区间","条件筛选","人工判断","其他"},base,(TEXT('📌 命中追踪'!B:B04,"YYYY-MM")=mon)*('📌 命中追踪'!L:L04="✅ 命中"),mtx,--( '📌 命中追踪'!N:N04=names),counts,MMULT(TRANSPOSE(base*1),mtx),IF(MAX(counts)=0,"—",INDEX(names,MATCH(MAX(counts),counts,0))))) | H23: =IF(OR(B23="",F23=""),"",IF(ROW()=6,"—",IF(F22="","—",IF(F23>F22,"📈 上升",IF(F23<F22,"📉 下降","➡ 持平")))))
A24: 19 | C24: =IF(B24="","",SUMPRODUCT((TEXT('📌 命中追踪'!B5:B104,"YYYY-MM")=TEXT(B24,"YYYY-MM"))*1)) | D24: =IF(B24="","",SUMPRODUCT((TEXT('📌 命中追踪'!B5:B104,"YYYY-MM")=TEXT(B24,"YYYY-MM"))*('📌 命中追踪'!L5:L104<>""))) | E24: =IF(B24="","",SUMPRODUCT((TEXT('📌 命中追踪'!B5:B104,"YYYY-MM")=TEXT(B24,"YYYY-MM"))*('📌 命中追踪'!L5:L104="✅ 命中"))) | F24: =IFERROR(E24/D24,"") | G24: =IF(B24="","",LET(mon,TEXT(B24,"YYYY-MM"),names,{"数根链","配对分析","冷热库","四步向导","工作台","点数区间","条件筛选","人工判断","其他"},base,(TEXT('📌 命中追踪'!B:B04,"YYYY-MM")=mon)*('📌 命中追踪'!L:L04="✅ 命中"),mtx,--( '📌 命中追踪'!N:N04=names),counts,MMULT(TRANSPOSE(base*1),mtx),IF(MAX(counts)=0,"—",INDEX(names,MATCH(MAX(counts),counts,0))))) | H24: =IF(OR(B24="",F24=""),"",IF(ROW()=6,"—",IF(F23="","—",IF(F24>F23,"📈 上升",IF(F24<F23,"📉 下降","➡ 持平")))))
A25: 20 | C25: =IF(B25="","",SUMPRODUCT((TEXT('📌 命中追踪'!B5:B104,"YYYY-MM")=TEXT(B25,"YYYY-MM"))*1)) | D25: =IF(B25="","",SUMPRODUCT((TEXT('📌 命中追踪'!B5:B104,"YYYY-MM")=TEXT(B25,"YYYY-MM"))*('📌 命中追踪'!L5:L104<>""))) | E25: =IF(B25="","",SUMPRODUCT((TEXT('📌 命中追踪'!B5:B104,"YYYY-MM")=TEXT(B25,"YYYY-MM"))*('📌 命中追踪'!L5:L104="✅ 命中"))) | F25: =IFERROR(E25/D25,"") | G25: =IF(B25="","",LET(mon,TEXT(B25,"YYYY-MM"),names,{"数根链","配对分析","冷热库","四步向导","工作台","点数区间","条件筛选","人工判断","其他"},base,(TEXT('📌 命中追踪'!B:B04,"YYYY-MM")=mon)*('📌 命中追踪'!L:L04="✅ 命中"),mtx,--( '📌 命中追踪'!N:N04=names),counts,MMULT(TRANSPOSE(base*1),mtx),IF(MAX(counts)=0,"—",INDEX(names,MATCH(MAX(counts),counts,0))))) | H25: =IF(OR(B25="",F25=""),"",IF(ROW()=6,"—",IF(F24="","—",IF(F25>F24,"📈 上升",IF(F25<F24,"📉 下降","➡ 持平")))))
A26: 21 | C26: =IF(B26="","",SUMPRODUCT((TEXT('📌 命中追踪'!B5:B104,"YYYY-MM")=TEXT(B26,"YYYY-MM"))*1)) | D26: =IF(B26="","",SUMPRODUCT((TEXT('📌 命中追踪'!B5:B104,"YYYY-MM")=TEXT(B26,"YYYY-MM"))*('📌 命中追踪'!L5:L104<>""))) | E26: =IF(B26="","",SUMPRODUCT((TEXT('📌 命中追踪'!B5:B104,"YYYY-MM")=TEXT(B26,"YYYY-MM"))*('📌 命中追踪'!L5:L104="✅ 命中"))) | F26: =IFERROR(E26/D26,"") | G26: =IF(B26="","",LET(mon,TEXT(B26,"YYYY-MM"),names,{"数根链","配对分析","冷热库","四步向导","工作台","点数区间","条件筛选","人工判断","其他"},base,(TEXT('📌 命中追踪'!B:B04,"YYYY-MM")=mon)*('📌 命中追踪'!L:L04="✅ 命中"),mtx,--( '📌 命中追踪'!N:N04=names),counts,MMULT(TRANSPOSE(base*1),mtx),IF(MAX(counts)=0,"—",INDEX(names,MATCH(MAX(counts),counts,0))))) | H26: =IF(OR(B26="",F26=""),"",IF(ROW()=6,"—",IF(F25="","—",IF(F26>F25,"📈 上升",IF(F26<F25,"📉 下降","➡ 持平")))))
A27: 22 | C27: =IF(B27="","",SUMPRODUCT((TEXT('📌 命中追踪'!B5:B104,"YYYY-MM")=TEXT(B27,"YYYY-MM"))*1)) | D27: =IF(B27="","",SUMPRODUCT((TEXT('📌 命中追踪'!B5:B104,"YYYY-MM")=TEXT(B27,"YYYY-MM"))*('📌 命中追踪'!L5:L104<>""))) | E27: =IF(B27="","",SUMPRODUCT((TEXT('📌 命中追踪'!B5:B104,"YYYY-MM")=TEXT(B27,"YYYY-MM"))*('📌 命中追踪'!L5:L104="✅ 命中"))) | F27: =IFERROR(E27/D27,"") | G27: =IF(B27="","",LET(mon,TEXT(B27,"YYYY-MM"),names,{"数根链","配对分析","冷热库","四步向导","工作台","点数区间","条件筛选","人工判断","其他"},base,(TEXT('📌 命中追踪'!B:B04,"YYYY-MM")=mon)*('📌 命中追踪'!L:L04="✅ 命中"),mtx,--( '📌 命中追踪'!N:N04=names),counts,MMULT(TRANSPOSE(base*1),mtx),IF(MAX(counts)=0,"—",INDEX(names,MATCH(MAX(counts),counts,0))))) | H27: =IF(OR(B27="",F27=""),"",IF(ROW()=6,"—",IF(F26="","—",IF(F27>F26,"📈 上升",IF(F27<F26,"📉 下降","➡ 持平")))))
A28: 23 | C28: =IF(B28="","",SUMPRODUCT((TEXT('📌 命中追踪'!B5:B104,"YYYY-MM")=TEXT(B28,"YYYY-MM"))*1)) | D28: =IF(B28="","",SUMPRODUCT((TEXT('📌 命中追踪'!B5:B104,"YYYY-MM")=TEXT(B28,"YYYY-MM"))*('📌 命中追踪'!L5:L104<>""))) | E28: =IF(B28="","",SUMPRODUCT((TEXT('📌 命中追踪'!B5:B104,"YYYY-MM")=TEXT(B28,"YYYY-MM"))*('📌 命中追踪'!L5:L104="✅ 命中"))) | F28: =IFERROR(E28/D28,"") | G28: =IF(B28="","",LET(mon,TEXT(B28,"YYYY-MM"),names,{"数根链","配对分析","冷热库","四步向导","工作台","点数区间","条件筛选","人工判断","其他"},base,(TEXT('📌 命中追踪'!B:B04,"YYYY-MM")=mon)*('📌 命中追踪'!L:L04="✅ 命中"),mtx,--( '📌 命中追踪'!N:N04=names),counts,MMULT(TRANSPOSE(base*1),mtx),IF(MAX(counts)=0,"—",INDEX(names,MATCH(MAX(counts),counts,0))))) | H28: =IF(OR(B28="",F28=""),"",IF(ROW()=6,"—",IF(F27="","—",IF(F28>F27,"📈 上升",IF(F28<F27,"📉 下降","➡ 持平")))))
A29: 24 | C29: =IF(B29="","",SUMPRODUCT((TEXT('📌 命中追踪'!B5:B104,"YYYY-MM")=TEXT(B29,"YYYY-MM"))*1)) | D29: =IF(B29="","",SUMPRODUCT((TEXT('📌 命中追踪'!B5:B104,"YYYY-MM")=TEXT(B29,"YYYY-MM"))*('📌 命中追踪'!L5:L104<>""))) | E29: =IF(B29="","",SUMPRODUCT((TEXT('📌 命中追踪'!B5:B104,"YYYY-MM")=TEXT(B29,"YYYY-MM"))*('📌 命中追踪'!L5:L104="✅ 命中"))) | F29: =IFERROR(E29/D29,"") | G29: =IF(B29="","",LET(mon,TEXT(B29,"YYYY-MM"),names,{"数根链","配对分析","冷热库","四步向导","工作台","点数区间","条件筛选","人工判断","其他"},base,(TEXT('📌 命中追踪'!B:B04,"YYYY-MM")=mon)*('📌 命中追踪'!L:L04="✅ 命中"),mtx,--( '📌 命中追踪'!N:N04=names),counts,MMULT(TRANSPOSE(base*1),mtx),IF(MAX(counts)=0,"—",INDEX(names,MATCH(MAX(counts),counts,0))))) | H29: =IF(OR(B29="",F29=""),"",IF(ROW()=6,"—",IF(F28="","—",IF(F29>F28,"📈 上升",IF(F29<F28,"📉 下降","➡ 持平")))))
A33: 📈 累计汇总
A34: 总记录期数 | C34: =COUNTA('📌 命中追踪'!B5:B104)
A35: 总命中次数 | C35: =COUNTIF('📌 命中追踪'!L5:L104,"✅ 命中")
A36: 总体命中率 | C36: =IFERROR(COUNTIF('📌 命中追踪'!L5:L104,"✅ 命中")/COUNTIF('📌 命中追踪'!L5:L104,"<>"),0)
A37: 最高月命中率 | C37: =IFERROR(MAX(F6:F29),0)

Sheet 💡 透视表指引
B2: 💡 透视表指引 — 用导出数据做更深分析
B4: 分析1：数根季节性（最实用）
B5: 目的 | C5: 找出哪个数根在哪几个月特别活跃
B6: 操作步骤 | C6: ① 打开导出的 Excel → 选择任一市场 Sheet
C7: ② 点击「插入」→「数据透视表」
C8: ③ 行：拖入日期列（按月分组）
C9: ④ 列：拖入后3D数根（B3 root）
C10: ⑤ 值：计数
B11: 解读方法 | C11: 某个数根在某月特别高 → 下次该月重点关注该数根
B13: 分析2：冷热周期分析
B14: 目的 | C14: 找出某个后3D数根平均多少期出现一次
B15: 操作步骤 | C15: ① 筛选 B3 root 某个值（如：3）
C16: ② 看日期列，计算相邻出现的期数差
C17: ③ 用 AVERAGE 算平均间隔
B18: 实际意义 | C18: 平均间隔是你判断「冷号应该出了」的依据
B20: 分析3：首位 + 后3D 联合频率
B21: 目的 | C21: 验证系统「配对分析」功能的历史数据
B22: 操作步骤 | C22: ① 行：后3D 数根
C23: ② 列：首位数字（号码的第1位）
C24: ③ 值：计数
B25: 解读方法 | C25: 某格子数字特别大 → 那个组合历史上频繁出现
B27: 分析4：点数区间走势
B28: 目的 | C28: 看近6个月4D点数是否有漂移趋势
B29: 操作步骤 | C29: ① 选日期列 + 4D点数列
C30: ② 插入折线图
C31: ③ 加移动平均线（右键数据系列 → 趋势线）
B33: 重要提示
B34: 导出文件列名说明 | C34: F=前2D, M=中2D, B=后2D；数字后缀1/2/3=头/二/三奖；root=数根；parity=奇偶
B35: 建议分析期数 | C35: 至少100期以上，数根分析建议200期+
B36: 颜色含义 | C36: 单元格颜色与系统页面一致：蓝=G1数根(1,4,7), 黄=G2(2,5,8), 粉=G3(3,6,9)

Sheet 🔢 位数追踪
A2: 🔢 四位追踪表 — 千位·百位·十位·个位 各自的大小·单双·连续走势 → 自动输出下期筛选条件
A3: 📥 输入 | H3: 🔷 千位 (第1位) | Q3: 🟣 百位 (第2位) | Z3: 🟢 十位 (第3位) | AI3: 🟠 个位 (第4位) | AR3: ✅ 命中验证 | AW3: 备注
A4: # | B4: 日期 | C4: 市场 | D4: 头奖 | E4: 二奖 | F4: 三奖 | H4: 头千 | I4: 二千 | J4: 三千 | K4: 大小信号 | L4: 单双信号 | M4: 连续 | N4: ⚠️预警 | O4: 下期建议 | Q4: 头百 | R4: 二百 | S4: 三百 | T4: 大小信号 | U4: 单双信号 | V4: 连续 | W4: ⚠️预警 | X4: 下期建议 | Z4: 头十 | AA4: 二十 | AB4: 三十 | AC4: 大小信号 | AD4: 单双信号 | AE4: 连续 | AF4: ⚠️预警 | AG4: 下期建议 | AI4: 头个 | AJ4: 二个 | AK4: 三个 | AL4: 大小信号 | AM4: 单双信号 | AN4: 连续 | AO4: ⚠️预警 | AP4: 下期建议 | AR4: 命中千位 | AS4: 命中百位 | AT4: 命中十位 | AU4: 命中个位 | AW4: 备注
A5: 1 | B5: 2026-05-02 | C5: 万能 | D5: 1109 | E5: 3856 | F5: 0175 | H5: =IF(D5="","",VALUE(MID(TEXT(D5,"0000"),1,1))) | I5: =IF(E5="","",VALUE(MID(TEXT(E5,"0000"),1,1))) | J5: =IF(F5="","",VALUE(MID(TEXT(F5,"0000"),1,1))) | K5: =IF(D5="","",IF(COUNTIF(H5:J5,">=5")=3,"🔴 全大",IF(COUNTIF(H5:J5,">=5")=0,"🔵 全小",IF(COUNTIF(H5:J5,">=5")=2,"▲ 偏大","▼ 偏小")))) | L5: =IF(D5="","",IF((MOD(H5,2)=1)+(MOD(I5,2)=1)+(MOD(J5,2)=1)=3,"⚫ 全单",IF((MOD(H5,2)=1)+(MOD(I5,2)=1)+(MOD(J5,2)=1)=0,"🟣 全双",IF((MOD(H5,2)=1)+(MOD(I5,2)=1)+(MOD(J5,2)=1)=2,"◑ 偏单","◑ 偏双")))) | M5: =IF(D5="","",1) | N5: =IF(M5="","",IF(M5>=4,"🚨 "&M5&"期·警惕反转",IF(M5=3,"⚠️ 3期连续","—"))) | O5: =IF(K5="","—",IF(ISNUMBER(SEARCH("大",K5)),IF(OR(K5="🔴 全大"),IF(M5>=4,"大xxx 强·⚠️反转?",IF(M5=3,"大xxx 强·连3期","大xxx ✅强用")),"大xxx △弱参考"),IF(OR(K5="🔵 全小"),IF(M5>=4,"小xxx 强·⚠️反转?",IF(M5=3,"小xxx 强·连3期","小xxx ✅强用")),"小xxx △弱参考"))) | Q5: =IF(D5="","",VALUE(MID(TEXT(D5,"0000"),2,1))) | R5: =IF(E5="","",VALUE(MID(TEXT(E5,"0000"),2,1))) | S5: =IF(F5="","",VALUE(MID(TEXT(F5,"0000"),2,1))) | T5: =IF(D5="","",IF(COUNTIF(Q5:S5,">=5")=3,"🔴 全大",IF(COUNTIF(Q5:S5,">=5")=0,"🔵 全小",IF(COUNTIF(Q5:S5,">=5")=2,"▲ 偏大","▼ 偏小")))) | U5: =IF(D5="","",IF((MOD(Q5,2)=1)+(MOD(R5,2)=1)+(MOD(S5,2)=1)=3,"⚫ 全单",IF((MOD(Q5,2)=1)+(MOD(R5,2)=1)+(MOD(S5,2)=1)=0,"🟣 全双",IF((MOD(Q5,2)=1)+(MOD(R5,2)=1)+(MOD(S5,2)=1)=2,"◑ 偏单","◑ 偏双")))) | V5: =IF(D5="","",1) | W5: =IF(V5="","",IF(V5>=4,"🚨 "&V5&"期·警惕反转",IF(V5=3,"⚠️ 3期连续","—"))) | X5: =IF(T5="","—",IF(ISNUMBER(SEARCH("大",T5)),IF(OR(T5="🔴 全大"),IF(V5>=4,"x大xx 强·⚠️反转?",IF(V5=3,"x大xx 强·连3期","x大xx ✅强用")),"x大xx △弱参考"),IF(OR(T5="🔵 全小"),IF(V5>=4,"x小xx 强·⚠️反转?",IF(V5=3,"x小xx 强·连3期","x小xx ✅强用")),"x小xx △弱参考"))) | Z5: =IF(D5="","",VALUE(MID(TEXT(D5,"0000"),3,1))) | AA5: =IF(E5="","",VALUE(MID(TEXT(E5,"0000"),3,1))) | AB5: =IF(F5="","",VALUE(MID(TEXT(F5,"0000"),3,1))) | AC5: =IF(D5="","",IF(COUNTIF(Z5:AB5,">=5")=3,"🔴 全大",IF(COUNTIF(Z5:AB5,">=5")=0,"🔵 全小",IF(COUNTIF(Z5:AB5,">=5")=2,"▲ 偏大","▼ 偏小")))) | AD5: =IF(D5="","",IF((MOD(Z5,2)=1)+(MOD(AA5,2)=1)+(MOD(AB5,2)=1)=3,"⚫ 全单",IF((MOD(Z5,2)=1)+(MOD(AA5,2)=1)+(MOD(AB5,2)=1)=0,"🟣 全双",IF((MOD(Z5,2)=1)+(MOD(AA5,2)=1)+(MOD(AB5,2)=1)=2,"◑ 偏单","◑ 偏双")))) | AE5: =IF(D5="","",1) | AF5: =IF(AE5="","",IF(AE5>=4,"🚨 "&AE5&"期·警惕反转",IF(AE5=3,"⚠️ 3期连续","—"))) | AG5: =IF(AC5="","—",IF(ISNUMBER(SEARCH("大",AC5)),IF(OR(AC5="🔴 全大"),IF(AE5>=4,"xx大x 强·⚠️反转?",IF(AE5=3,"xx大x 强·连3期","xx大x ✅强用")),"xx大x △弱参考"),IF(OR(AC5="🔵 全小"),IF(AE5>=4,"xx小x 强·⚠️反转?",IF(AE5=3,"xx小x 强·连3期","xx小x ✅强用")),"xx小x △弱参考"))) | AI5: =IF(D5="","",VALUE(MID(TEXT(D5,"0000"),4,1))) | AJ5: =IF(E5="","",VALUE(MID(TEXT(E5,"0000"),4,1))) | AK5: =IF(F5="","",VALUE(MID(TEXT(F5,"0000"),4,1))) | AL5: =IF(D5="","",IF(COUNTIF(AI5:AK5,">=5")=3,"🔴 全大",IF(COUNTIF(AI5:AK5,">=5")=0,"🔵 全小",IF(COUNTIF(AI5:AK5,">=5")=2,"▲ 偏大","▼ 偏小")))) | AM5: =IF(D5="","",IF((MOD(AI5,2)=1)+(MOD(AJ5,2)=1)+(MOD(AK5,2)=1)=3,"⚫ 全单",IF((MOD(AI5,2)=1)+(MOD(AJ5,2)=1)+(MOD(AK5,2)=1)=0,"🟣 全双",IF((MOD(AI5,2)=1)+(MOD(AJ5,2)=1)+(MOD(AK5,2)=1)=2,"◑ 偏单","◑ 偏双")))) | AN5: =IF(D5="","",1) | AO5: =IF(AN5="","",IF(AN5>=4,"🚨 "&AN5&"期·警惕反转",IF(AN5=3,"⚠️ 3期连续","—"))) | AP5: =IF(AL5="","—",IF(ISNUMBER(SEARCH("大",AL5)),IF(OR(AL5="🔴 全大"),IF(AN5>=4,"xxx大 强·⚠️反转?",IF(AN5=3,"xxx大 强·连3期","xxx大 ✅强用")),"xxx大 △弱参考"),IF(OR(AL5="🔵 全小"),IF(AN5>=4,"xxx小 强·⚠️反转?",IF(AN5=3,"xxx小 强·连3期","xxx小 ✅强用")),"xxx小 △弱参考"))) | AR5: — | AS5: — | AT5: — | AU5: —
A6: 2 | B6: 2026-05-03 | C6: 万能 | D6: 0405 | E6: 2299 | F6: 1712 | H6: =IF(D6="","",VALUE(MID(TEXT(D6,"0000"),1,1))) | I6: =IF(E6="","",VALUE(MID(TEXT(E6,"0000"),1,1))) | J6: =IF(F6="","",VALUE(MID(TEXT(F6,"0000"),1,1))) | K6: =IF(D6="","",IF(COUNTIF(H6:J6,">=5")=3,"🔴 全大",IF(COUNTIF(H6:J6,">=5")=0,"🔵 全小",IF(COUNTIF(H6:J6,">=5")=2,"▲ 偏大","▼ 偏小")))) | L6: =IF(D6="","",IF((MOD(H6,2)=1)+(MOD(I6,2)=1)+(MOD(J6,2)=1)=3,"⚫ 全单",IF((MOD(H6,2)=1)+(MOD(I6,2)=1)+(MOD(J6,2)=1)=0,"🟣 全双",IF((MOD(H6,2)=1)+(MOD(I6,2)=1)+(MOD(J6,2)=1)=2,"◑ 偏单","◑ 偏双")))) | M6: =IF(D6="","",IF(D5="",1,IF(ISNUMBER(SEARCH("大",K6))=ISNUMBER(SEARCH("大",K5)),M5+1,1))) | N6: =IF(M6="","",IF(M6>=4,"🚨 "&M6&"期·警惕反转",IF(M6=3,"⚠️ 3期连续","—"))) | O6: =IF(K6="","—",IF(ISNUMBER(SEARCH("大",K6)),IF(OR(K6="🔴 全大"),IF(M6>=4,"大xxx 强·⚠️反转?",IF(M6=3,"大xxx 强·连3期","大xxx ✅强用")),"大xxx △弱参考"),IF(OR(K6="🔵 全小"),IF(M6>=4,"小xxx 强·⚠️反转?",IF(M6=3,"小xxx 强·连3期","小xxx ✅强用")),"小xxx △弱参考"))) | Q6: =IF(D6="","",VALUE(MID(TEXT(D6,"0000"),2,1))) | R6: =IF(E6="","",VALUE(MID(TEXT(E6,"0000"),2,1))) | S6: =IF(F6="","",VALUE(MID(TEXT(F6,"0000"),2,1))) | T6: =IF(D6="","",IF(COUNTIF(Q6:S6,">=5")=3,"🔴 全大",IF(COUNTIF(Q6:S6,">=5")=0,"🔵 全小",IF(COUNTIF(Q6:S6,">=5")=2,"▲ 偏大","▼ 偏小")))) | U6: =IF(D6="","",IF((MOD(Q6,2)=1)+(MOD(R6,2)=1)+(MOD(S6,2)=1)=3,"⚫ 全单",IF((MOD(Q6,2)=1)+(MOD(R6,2)=1)+(MOD(S6,2)=1)=0,"🟣 全双",IF((MOD(Q6,2)=1)+(MOD(R6,2)=1)+(MOD(S6,2)=1)=2,"◑ 偏单","◑ 偏双")))) | V6: =IF(D6="","",IF(D5="",1,IF(ISNUMBER(SEARCH("大",T6))=ISNUMBER(SEARCH("大",T5)),V5+1,1))) | W6: =IF(V6="","",IF(V6>=4,"🚨 "&V6&"期·警惕反转",IF(V6=3,"⚠️ 3期连续","—"))) | X6: =IF(T6="","—",IF(ISNUMBER(SEARCH("大",T6)),IF(OR(T6="🔴 全大"),IF(V6>=4,"x大xx 强·⚠️反转?",IF(V6=3,"x大xx 强·连3期","x大xx ✅强用")),"x大xx △弱参考"),IF(OR(T6="🔵 全小"),IF(V6>=4,"x小xx 强·⚠️反转?",IF(V6=3,"x小xx 强·连3期","x小xx ✅强用")),"x小xx △弱参考"))) | Z6: =IF(D6="","",VALUE(MID(TEXT(D6,"0000"),3,1))) | AA6: =IF(E6="","",VALUE(MID(TEXT(E6,"0000"),3,1))) | AB6: =IF(F6="","",VALUE(MID(TEXT(F6,"0000"),3,1))) | AC6: =IF(D6="","",IF(COUNTIF(Z6:AB6,">=5")=3,"🔴 全大",IF(COUNTIF(Z6:AB6,">=5")=0,"🔵 全小",IF(COUNTIF(Z6:AB6,">=5")=2,"▲ 偏大","▼ 偏小")))) | AD6: =IF(D6="","",IF((MOD(Z6,2)=1)+(MOD(AA6,2)=1)+(MOD(AB6,2)=1)=3,"⚫ 全单",IF((MOD(Z6,2)=1)+(MOD(AA6,2)=1)+(MOD(AB6,2)=1)=0,"🟣 全双",IF((MOD(Z6,2)=1)+(MOD(AA6,2)=1)+(MOD(AB6,2)=1)=2,"◑ 偏单","◑ 偏双")))) | AE6: =IF(D6="","",IF(D5="",1,IF(ISNUMBER(SEARCH("大",AC6))=ISNUMBER(SEARCH("大",AC5)),AE5+1,1))) | AF6: =IF(AE6="","",IF(AE6>=4,"🚨 "&AE6&"期·警惕反转",IF(AE6=3,"⚠️ 3期连续","—"))) | AG6: =IF(AC6="","—",IF(ISNUMBER(SEARCH("大",AC6)),IF(OR(AC6="🔴 全大"),IF(AE6>=4,"xx大x 强·⚠️反转?",IF(AE6=3,"xx大x 强·连3期","xx大x ✅强用")),"xx大x △弱参考"),IF(OR(AC6="🔵 全小"),IF(AE6>=4,"xx小x 强·⚠️反转?",IF(AE6=3,"xx小x 强·连3期","xx小x ✅强用")),"xx小x △弱参考"))) | AI6: =IF(D6="","",VALUE(MID(TEXT(D6,"0000"),4,1))) | AJ6: =IF(E6="","",VALUE(MID(TEXT(E6,"0000"),4,1))) | AK6: =IF(F6="","",VALUE(MID(TEXT(F6,"0000"),4,1))) | AL6: =IF(D6="","",IF(COUNTIF(AI6:AK6,">=5")=3,"🔴 全大",IF(COUNTIF(AI6:AK6,">=5")=0,"🔵 全小",IF(COUNTIF(AI6:AK6,">=5")=2,"▲ 偏大","▼ 偏小")))) | AM6: =IF(D6="","",IF((MOD(AI6,2)=1)+(MOD(AJ6,2)=1)+(MOD(AK6,2)=1)=3,"⚫ 全单",IF((MOD(AI6,2)=1)+(MOD(AJ6,2)=1)+(MOD(AK6,2)=1)=0,"🟣 全双",IF((MOD(AI6,2)=1)+(MOD(AJ6,2)=1)+(MOD(AK6,2)=1)=2,"◑ 偏单","◑ 偏双")))) | AN6: =IF(D6="","",IF(D5="",1,IF(ISNUMBER(SEARCH("大",AL6))=ISNUMBER(SEARCH("大",AL5)),AN5+1,1))) | AO6: =IF(AN6="","",IF(AN6>=4,"🚨 "&AN6&"期·警惕反转",IF(AN6=3,"⚠️ 3期连续","—"))) | AP6: =IF(AL6="","—",IF(ISNUMBER(SEARCH("大",AL6)),IF(OR(AL6="🔴 全大"),IF(AN6>=4,"xxx大 强·⚠️反转?",IF(AN6=3,"xxx大 强·连3期","xxx大 ✅强用")),"xxx大 △弱参考"),IF(OR(AL6="🔵 全小"),IF(AN6>=4,"xxx小 强·⚠️反转?",IF(AN6=3,"xxx小 强·连3期","xxx小 ✅强用")),"xxx小 △弱参考"))) | AR6: =IF(OR(D6="",D5=""),"—",IF(K5="","—",IF(ISNUMBER(SEARCH("大",K5)),IF(COUNTIF(H6:J6,">=5")>=2,"✅","❌"),IF(COUNTIF(H6:J6,">=5")<=1,"✅","❌")))) | AS6: =IF(OR(D6="",D5=""),"—",IF(T5="","—",IF(ISNUMBER(SEARCH("大",T5)),IF(COUNTIF(Q6:S6,">=5")>=2,"✅","❌"),IF(COUNTIF(Q6:S6,">=5")<=1,"✅","❌")))) | AT6: =IF(OR(D6="",D5=""),"—",IF(AC5="","—",IF(ISNUMBER(SEARCH("大",AC5)),IF(COUNTIF(Z6:AB6,">=5")>=2,"✅","❌"),IF(COUNTIF(Z6:AB6,">=5")<=1,"✅","❌")))) | AU6: =IF(OR(D6="",D5=""),"—",IF(AL5="","—",IF(ISNUMBER(SEARCH("大",AL5)),IF(COUNTIF(AI6:AK6,">=5")>=2,"✅","❌"),IF(COUNTIF(AI6:AK6,">=5")<=1,"✅","❌"))))
A7: 3 | B7: 2026-05-06 | C7: 万能 | D7: 1902 | E7: 6845 | F7: 0935 | H7: =IF(D7="","",VALUE(MID(TEXT(D7,"0000"),1,1))) | I7: =IF(E7="","",VALUE(MID(TEXT(E7,"0000"),1,1))) | J7: =IF(F7="","",VALUE(MID(TEXT(F7,"0000"),1,1))) | K7: =IF(D7="","",IF(COUNTIF(H7:J7,">=5")=3,"🔴 全大",IF(COUNTIF(H7:J7,">=5")=0,"🔵 全小",IF(COUNTIF(H7:J7,">=5")=2,"▲ 偏大","▼ 偏小")))) | L7: =IF(D7="","",IF((MOD(H7,2)=1)+(MOD(I7,2)=1)+(MOD(J7,2)=1)=3,"⚫ 全单",IF((MOD(H7,2)=1)+(MOD(I7,2)=1)+(MOD(J7,2)=1)=0,"🟣 全双",IF((MOD(H7,2)=1)+(MOD(I7,2)=1)+(MOD(J7,2)=1)=2,"◑ 偏单","◑ 偏双")))) | M7: =IF(D7="","",IF(D6="",1,IF(ISNUMBER(SEARCH("大",K7))=ISNUMBER(SEARCH("大",K6)),M6+1,1))) | N7: =IF(M7="","",IF(M7>=4,"🚨 "&M7&"期·警惕反转",IF(M7=3,"⚠️ 3期连续","—"))) | O7: =IF(K7="","—",IF(ISNUMBER(SEARCH("大",K7)),IF(OR(K7="🔴 全大"),IF(M7>=4,"大xxx 强·⚠️反转?",IF(M7=3,"大xxx 强·连3期","大xxx ✅强用")),"大xxx △弱参考"),IF(OR(K7="🔵 全小"),IF(M7>=4,"小xxx 强·⚠️反转?",IF(M7=3,"小xxx 强·连3期","小xxx ✅强用")),"小xxx △弱参考"))) | Q7: =IF(D7="","",VALUE(MID(TEXT(D7,"0000"),2,1))) | R7: =IF(E7="","",VALUE(MID(TEXT(E7,"0000"),2,1))) | S7: =IF(F7="","",VALUE(MID(TEXT(F7,"0000"),2,1))) | T7: =IF(D7="","",IF(COUNTIF(Q7:S7,">=5")=3,"🔴 全大",IF(COUNTIF(Q7:S7,">=5")=0,"🔵 全小",IF(COUNTIF(Q7:S7,">=5")=2,"▲ 偏大","▼ 偏小")))) | U7: =IF(D7="","",IF((MOD(Q7,2)=1)+(MOD(R7,2)=1)+(MOD(S7,2)=1)=3,"⚫ 全单",IF((MOD(Q7,2)=1)+(MOD(R7,2)=1)+(MOD(S7,2)=1)=0,"🟣 全双",IF((MOD(Q7,2)=1)+(MOD(R7,2)=1)+(MOD(S7,2)=1)=2,"◑ 偏单","◑ 偏双")))) | V7: =IF(D7="","",IF(D6="",1,IF(ISNUMBER(SEARCH("大",T7))=ISNUMBER(SEARCH("大",T6)),V6+1,1))) | W7: =IF(V7="","",IF(V7>=4,"🚨 "&V7&"期·警惕反转",IF(V7=3,"⚠️ 3期连续","—"))) | X7: =IF(T7="","—",IF(ISNUMBER(SEARCH("大",T7)),IF(OR(T7="🔴 全大"),IF(V7>=4,"x大xx 强·⚠️反转?",IF(V7=3,"x大xx 强·连3期","x大xx ✅强用")),"x大xx △弱参考"),IF(OR(T7="🔵 全小"),IF(V7>=4,"x小xx 强·⚠️反转?",IF(V7=3,"x小xx 强·连3期","x小xx ✅强用")),"x小xx △弱参考"))) | Z7: =IF(D7="","",VALUE(MID(TEXT(D7,"0000"),3,1))) | AA7: =IF(E7="","",VALUE(MID(TEXT(E7,"0000"),3,1))) | AB7: =IF(F7="","",VALUE(MID(TEXT(F7,"0000"),3,1))) | AC7: =IF(D7="","",IF(COUNTIF(Z7:AB7,">=5")=3,"🔴 全大",IF(COUNTIF(Z7:AB7,">=5")=0,"🔵 全小",IF(COUNTIF(Z7:AB7,">=5")=2,"▲ 偏大","▼ 偏小")))) | AD7: =IF(D7="","",IF((MOD(Z7,2)=1)+(MOD(AA7,2)=1)+(MOD(AB7,2)=1)=3,"⚫ 全单",IF((MOD(Z7,2)=1)+(MOD(AA7,2)=1)+(MOD(AB7,2)=1)=0,"🟣 全双",IF((MOD(Z7,2)=1)+(MOD(AA7,2)=1)+(MOD(AB7,2)=1)=2,"◑ 偏单","◑ 偏双")))) | AE7: =IF(D7="","",IF(D6="",1,IF(ISNUMBER(SEARCH("大",AC7))=ISNUMBER(SEARCH("大",AC6)),AE6+1,1))) | AF7: =IF(AE7="","",IF(AE7>=4,"🚨 "&AE7&"期·警惕反转",IF(AE7=3,"⚠️ 3期连续","—"))) | AG7: =IF(AC7="","—",IF(ISNUMBER(SEARCH("大",AC7)),IF(OR(AC7="🔴 全大"),IF(AE7>=4,"xx大x 强·⚠️反转?",IF(AE7=3,"xx大x 强·连3期","xx大x ✅强用")),"xx大x △弱参考"),IF(OR(AC7="🔵 全小"),IF(AE7>=4,"xx小x 强·⚠️反转?",IF(AE7=3,"xx小x 强·连3期","xx小x ✅强用")),"xx小x △弱参考"))) | AI7: =IF(D7="","",VALUE(MID(TEXT(D7,"0000"),4,1))) | AJ7: =IF(E7="","",VALUE(MID(TEXT(E7,"0000"),4,1))) | AK7: =IF(F7="","",VALUE(MID(TEXT(F7,"0000"),4,1))) | AL7: =IF(D7="","",IF(COUNTIF(AI7:AK7,">=5")=3,"🔴 全大",IF(COUNTIF(AI7:AK7,">=5")=0,"🔵 全小",IF(COUNTIF(AI7:AK7,">=5")=2,"▲ 偏大","▼ 偏小")))) | AM7: =IF(D7="","",IF((MOD(AI7,2)=1)+(MOD(AJ7,2)=1)+(MOD(AK7,2)=1)=3,"⚫ 全单",IF((MOD(AI7,2)=1)+(MOD(AJ7,2)=1)+(MOD(AK7,2)=1)=0,"🟣 全双",IF((MOD(AI7,2)=1)+(MOD(AJ7,2)=1)+(MOD(AK7,2)=1)=2,"◑ 偏单","◑ 偏双")))) | AN7: =IF(D7="","",IF(D6="",1,IF(ISNUMBER(SEARCH("大",AL7))=ISNUMBER(SEARCH("大",AL6)),AN6+1,1))) | AO7: =IF(AN7="","",IF(AN7>=4,"🚨 "&AN7&"期·警惕反转",IF(AN7=3,"⚠️ 3期连续","—"))) | AP7: =IF(AL7="","—",IF(ISNUMBER(SEARCH("大",AL7)),IF(OR(AL7="🔴 全大"),IF(AN7>=4,"xxx大 强·⚠️反转?",IF(AN7=3,"xxx大 强·连3期","xxx大 ✅强用")),"xxx大 △弱参考"),IF(OR(AL7="🔵 全小"),IF(AN7>=4,"xxx小 强·⚠️反转?",IF(AN7=3,"xxx小 强·连3期","xxx小 ✅强用")),"xxx小 △弱参考"))) | AR7: =IF(OR(D7="",D6=""),"—",IF(K6="","—",IF(ISNUMBER(SEARCH("大",K6)),IF(COUNTIF(H7:J7,">=5")>=2,"✅","❌"),IF(COUNTIF(H7:J7,">=5")<=1,"✅","❌")))) | AS7: =IF(OR(D7="",D6=""),"—",IF(T6="","—",IF(ISNUMBER(SEARCH("大",T6)),IF(COUNTIF(Q7:S7,">=5")>=2,"✅","❌"),IF(COUNTIF(Q7:S7,">=5")<=1,"✅","❌")))) | AT7: =IF(OR(D7="",D6=""),"—",IF(AC6="","—",IF(ISNUMBER(SEARCH("大",AC6)),IF(COUNTIF(Z7:AB7,">=5")>=2,"✅","❌"),IF(COUNTIF(Z7:AB7,">=5")<=1,"✅","❌")))) | AU7: =IF(OR(D7="",D6=""),"—",IF(AL6="","—",IF(ISNUMBER(SEARCH("大",AL6)),IF(COUNTIF(AI7:AK7,">=5")>=2,"✅","❌"),IF(COUNTIF(AI7:AK7,">=5")<=1,"✅","❌"))))
A8: 4 | B8: 2026-05-09 | C8: 万能 | D8: 4965 | E8: 2753 | F8: 7281 | H8: =IF(D8="","",VALUE(MID(TEXT(D8,"0000"),1,1))) | I8: =IF(E8="","",VALUE(MID(TEXT(E8,"0000"),1,1))) | J8: =IF(F8="","",VALUE(MID(TEXT(F8,"0000"),1,1))) | K8: =IF(D8="","",IF(COUNTIF(H8:J8,">=5")=3,"🔴 全大",IF(COUNTIF(H8:J8,">=5")=0,"🔵 全小",IF(COUNTIF(H8:J8,">=5")=2,"▲ 偏大","▼ 偏小")))) | L8: =IF(D8="","",IF((MOD(H8,2)=1)+(MOD(I8,2)=1)+(MOD(J8,2)=1)=3,"⚫ 全单",IF((MOD(H8,2)=1)+(MOD(I8,2)=1)+(MOD(J8,2)=1)=0,"🟣 全双",IF((MOD(H8,2)=1)+(MOD(I8,2)=1)+(MOD(J8,2)=1)=2,"◑ 偏单","◑ 偏双")))) | M8: =IF(D8="","",IF(D7="",1,IF(ISNUMBER(SEARCH("大",K8))=ISNUMBER(SEARCH("大",K7)),M7+1,1))) | N8: =IF(M8="","",IF(M8>=4,"🚨 "&M8&"期·警惕反转",IF(M8=3,"⚠️ 3期连续","—"))) | O8: =IF(K8="","—",IF(ISNUMBER(SEARCH("大",K8)),IF(OR(K8="🔴 全大"),IF(M8>=4,"大xxx 强·⚠️反转?",IF(M8=3,"大xxx 强·连3期","大xxx ✅强用")),"大xxx △弱参考"),IF(OR(K8="🔵 全小"),IF(M8>=4,"小xxx 强·⚠️反转?",IF(M8=3,"小xxx 强·连3期","小xxx ✅强用")),"小xxx △弱参考"))) | Q8: =IF(D8="","",VALUE(MID(TEXT(D8,"0000"),2,1))) | R8: =IF(E8="","",VALUE(MID(TEXT(E8,"0000"),2,1))) | S8: =IF(F8="","",VALUE(MID(TEXT(F8,"0000"),2,1))) | T8: =IF(D8="","",IF(COUNTIF(Q8:S8,">=5")=3,"🔴 全大",IF(COUNTIF(Q8:S8,">=5")=0,"🔵 全小",IF(COUNTIF(Q8:S8,">=5")=2,"▲ 偏大","▼ 偏小")))) | U8: =IF(D8="","",IF((MOD(Q8,2)=1)+(MOD(R8,2)=1)+(MOD(S8,2)=1)=3,"⚫ 全单",IF((MOD(Q8,2)=1)+(MOD(R8,2)=1)+(MOD(S8,2)=1)=0,"🟣 全双",IF((MOD(Q8,2)=1)+(MOD(R8,2)=1)+(MOD(S8,2)=1)=2,"◑ 偏单","◑ 偏双")))) | V8: =IF(D8="","",IF(D7="",1,IF(ISNUMBER(SEARCH("大",T8))=ISNUMBER(SEARCH("大",T7)),V7+1,1))) | W8: =IF(V8="","",IF(V8>=4,"🚨 "&V8&"期·警惕反转",IF(V8=3,"⚠️ 3期连续","—"))) | X8: =IF(T8="","—",IF(ISNUMBER(SEARCH("大",T8)),IF(OR(T8="🔴 全大"),IF(V8>=4,"x大xx 强·⚠️反转?",IF(V8=3,"x大xx 强·连3期","x大xx ✅强用")),"x大xx △弱参考"),IF(OR(T8="🔵 全小"),IF(V8>=4,"x小xx 强·⚠️反转?",IF(V8=3,"x小xx 强·连3期","x小xx ✅强用")),"x小xx △弱参考"))) | Z8: =IF(D8="","",VALUE(MID(TEXT(D8,"0000"),3,1))) | AA8: =IF(E8="","",VALUE(MID(TEXT(E8,"0000"),3,1))) | AB8: =IF(F8="","",VALUE(MID(TEXT(F8,"0000"),3,1))) | AC8: =IF(D8="","",IF(COUNTIF(Z8:AB8,">=5")=3,"🔴 全大",IF(COUNTIF(Z8:AB8,">=5")=0,"🔵 全小",IF(COUNTIF(Z8:AB8,">=5")=2,"▲ 偏大","▼ 偏小")))) | AD8: =IF(D8="","",IF((MOD(Z8,2)=1)+(MOD(AA8,2)=1)+(MOD(AB8,2)=1)=3,"⚫ 全单",IF((MOD(Z8,2)=1)+(MOD(AA8,2)=1)+(MOD(AB8,2)=1)=0,"🟣 全双",IF((MOD(Z8,2)=1)+(MOD(AA8,2)=1)+(MOD(AB8,2)=1)=2,"◑ 偏单","◑ 偏双")))) | AE8: =IF(D8="","",IF(D7="",1,IF(ISNUMBER(SEARCH("大",AC8))=ISNUMBER(SEARCH("大",AC7)),AE7+1,1))) | AF8: =IF(AE8="","",IF(AE8>=4,"🚨 "&AE8&"期·警惕反转",IF(AE8=3,"⚠️ 3期连续","—"))) | AG8: =IF(AC8="","—",IF(ISNUMBER(SEARCH("大",AC8)),IF(OR(AC8="🔴 全大"),IF(AE8>=4,"xx大x 强·⚠️反转?",IF(AE8=3,"xx大x 强·连3期","xx大x ✅强用")),"xx大x △弱参考"),IF(OR(AC8="🔵 全小"),IF(AE8>=4,"xx小x 强·⚠️反转?",IF(AE8=3,"xx小x 强·连3期","xx小x ✅强用")),"xx小x △弱参考"))) | AI8: =IF(D8="","",VALUE(MID(TEXT(D8,"0000"),4,1))) | AJ8: =IF(E8="","",VALUE(MID(TEXT(E8,"0000"),4,1))) | AK8: =IF(F8="","",VALUE(MID(TEXT(F8,"0000"),4,1))) | AL8: =IF(D8="","",IF(COUNTIF(AI8:AK8,">=5")=3,"🔴 全大",IF(COUNTIF(AI8:AK8,">=5")=0,"🔵 全小",IF(COUNTIF(AI8:AK8,">=5")=2,"▲ 偏大","▼ 偏小")))) | AM8: =IF(D8="","",IF((MOD(AI8,2)=1)+(MOD(AJ8,2)=1)+(MOD(AK8,2)=1)=3,"⚫ 全单",IF((MOD(AI8,2)=1)+(MOD(AJ8,2)=1)+(MOD(AK8,2)=1)=0,"🟣 全双",IF((MOD(AI8,2)=1)+(MOD(AJ8,2)=1)+(MOD(AK8,2)=1)=2,"◑ 偏单","◑ 偏双")))) | AN8: =IF(D8="","",IF(D7="",1,IF(ISNUMBER(SEARCH("大",AL8))=ISNUMBER(SEARCH("大",AL7)),AN7+1,1))) | AO8: =IF(AN8="","",IF(AN8>=4,"🚨 "&AN8&"期·警惕反转",IF(AN8=3,"⚠️ 3期连续","—"))) | AP8: =IF(AL8="","—",IF(ISNUMBER(SEARCH("大",AL8)),IF(OR(AL8="🔴 全大"),IF(AN8>=4,"xxx大 强·⚠️反转?",IF(AN8=3,"xxx大 强·连3期","xxx大 ✅强用")),"xxx大 △弱参考"),IF(OR(AL8="🔵 全小"),IF(AN8>=4,"xxx小 强·⚠️反转?",IF(AN8=3,"xxx小 强·连3期","xxx小 ✅强用")),"xxx小 △弱参考"))) | AR8: =IF(OR(D8="",D7=""),"—",IF(K7="","—",IF(ISNUMBER(SEARCH("大",K7)),IF(COUNTIF(H8:J8,">=5")>=2,"✅","❌"),IF(COUNTIF(H8:J8,">=5")<=1,"✅","❌")))) | AS8: =IF(OR(D8="",D7=""),"—",IF(T7="","—",IF(ISNUMBER(SEARCH("大",T7)),IF(COUNTIF(Q8:S8,">=5")>=2,"✅","❌"),IF(COUNTIF(Q8:S8,">=5")<=1,"✅","❌")))) | AT8: =IF(OR(D8="",D7=""),"—",IF(AC7="","—",IF(ISNUMBER(SEARCH("大",AC7)),IF(COUNTIF(Z8:AB8,">=5")>=2,"✅","❌"),IF(COUNTIF(Z8:AB8,">=5")<=1,"✅","❌")))) | AU8: =IF(OR(D8="",D7=""),"—",IF(AL7="","—",IF(ISNUMBER(SEARCH("大",AL7)),IF(COUNTIF(AI8:AK8,">=5")>=2,"✅","❌"),IF(COUNTIF(AI8:AK8,">=5")<=1,"✅","❌"))))
A9: 5 | B9: 2026-05-10 | C9: 万能 | D9: 4502 | E9: 2128 | F9: 2501 | H9: =IF(D9="","",VALUE(MID(TEXT(D9,"0000"),1,1))) | I9: =IF(E9="","",VALUE(MID(TEXT(E9,"0000"),1,1))) | J9: =IF(F9="","",VALUE(MID(TEXT(F9,"0000"),1,1))) | K9: =IF(D9="","",IF(COUNTIF(H9:J9,">=5")=3,"🔴 全大",IF(COUNTIF(H9:J9,">=5")=0,"🔵 全小",IF(COUNTIF(H9:J9,">=5")=2,"▲ 偏大","▼ 偏小")))) | L9: =IF(D9="","",IF((MOD(H9,2)=1)+(MOD(I9,2)=1)+(MOD(J9,2)=1)=3,"⚫ 全单",IF((MOD(H9,2)=1)+(MOD(I9,2)=1)+(MOD(J9,2)=1)=0,"🟣 全双",IF((MOD(H9,2)=1)+(MOD(I9,2)=1)+(MOD(J9,2)=1)=2,"◑ 偏单","◑ 偏双")))) | M9: =IF(D9="","",IF(D8="",1,IF(ISNUMBER(SEARCH("大",K9))=ISNUMBER(SEARCH("大",K8)),M8+1,1))) | N9: =IF(M9="","",IF(M9>=4,"🚨 "&M9&"期·警惕反转",IF(M9=3,"⚠️ 3期连续","—"))) | O9: =IF(K9="","—",IF(ISNUMBER(SEARCH("大",K9)),IF(OR(K9="🔴 全大"),IF(M9>=4,"大xxx 强·⚠️反转?",IF(M9=3,"大xxx 强·连3期","大xxx ✅强用")),"大xxx △弱参考"),IF(OR(K9="🔵 全小"),IF(M9>=4,"小xxx 强·⚠️反转?",IF(M9=3,"小xxx 强·连3期","小xxx ✅强用")),"小xxx △弱参考"))) | Q9: =IF(D9="","",VALUE(MID(TEXT(D9,"0000"),2,1))) | R9: =IF(E9="","",VALUE(MID(TEXT(E9,"0000"),2,1))) | S9: =IF(F9="","",VALUE(MID(TEXT(F9,"0000"),2,1))) | T9: =IF(D9="","",IF(COUNTIF(Q9:S9,">=5")=3,"🔴 全大",IF(COUNTIF(Q9:S9,">=5")=0,"🔵 全小",IF(COUNTIF(Q9:S9,">=5")=2,"▲ 偏大","▼ 偏小")))) | U9: =IF(D9="","",IF((MOD(Q9,2)=1)+(MOD(R9,2)=1)+(MOD(S9,2)=1)=3,"⚫ 全单",IF((MOD(Q9,2)=1)+(MOD(R9,2)=1)+(MOD(S9,2)=1)=0,"🟣 全双",IF((MOD(Q9,2)=1)+(MOD(R9,2)=1)+(MOD(S9,2)=1)=2,"◑ 偏单","◑ 偏双")))) | V9: =IF(D9="","",IF(D8="",1,IF(ISNUMBER(SEARCH("大",T9))=ISNUMBER(SEARCH("大",T8)),V8+1,1))) | W9: =IF(V9="","",IF(V9>=4,"🚨 "&V9&"期·警惕反转",IF(V9=3,"⚠️ 3期连续","—"))) | X9: =IF(T9="","—",IF(ISNUMBER(SEARCH("大",T9)),IF(OR(T9="🔴 全大"),IF(V9>=4,"x大xx 强·⚠️反转?",IF(V9=3,"x大xx 强·连3期","x大xx ✅强用")),"x大xx △弱参考"),IF(OR(T9="🔵 全小"),IF(V9>=4,"x小xx 强·⚠️反转?",IF(V9=3,"x小xx 强·连3期","x小xx ✅强用")),"x小xx △弱参考"))) | Z9: =IF(D9="","",VALUE(MID(TEXT(D9,"0000"),3,1))) | AA9: =IF(E9="","",VALUE(MID(TEXT(E9,"0000"),3,1))) | AB9: =IF(F9="","",VALUE(MID(TEXT(F9,"0000"),3,1))) | AC9: =IF(D9="","",IF(COUNTIF(Z9:AB9,">=5")=3,"🔴 全大",IF(COUNTIF(Z9:AB9,">=5")=0,"🔵 全小",IF(COUNTIF(Z9:AB9,">=5")=2,"▲ 偏大","▼ 偏小")))) | AD9: =IF(D9="","",IF((MOD(Z9,2)=1)+(MOD(AA9,2)=1)+(MOD(AB9,2)=1)=3,"⚫ 全单",IF((MOD(Z9,2)=1)+(MOD(AA9,2)=1)+(MOD(AB9,2)=1)=0,"🟣 全双",IF((MOD(Z9,2)=1)+(MOD(AA9,2)=1)+(MOD(AB9,2)=1)=2,"◑ 偏单","◑ 偏双")))) | AE9: =IF(D9="","",IF(D8="",1,IF(ISNUMBER(SEARCH("大",AC9))=ISNUMBER(SEARCH("大",AC8)),AE8+1,1))) | AF9: =IF(AE9="","",IF(AE9>=4,"🚨 "&AE9&"期·警惕反转",IF(AE9=3,"⚠️ 3期连续","—"))) | AG9: =IF(AC9="","—",IF(ISNUMBER(SEARCH("大",AC9)),IF(OR(AC9="🔴 全大"),IF(AE9>=4,"xx大x 强·⚠️反转?",IF(AE9=3,"xx大x 强·连3期","xx大x ✅强用")),"xx大x △弱参考"),IF(OR(AC9="🔵 全小"),IF(AE9>=4,"xx小x 强·⚠️反转?",IF(AE9=3,"xx小x 强·连3期","xx小x ✅强用")),"xx小x △弱参考"))) | AI9: =IF(D9="","",VALUE(MID(TEXT(D9,"0000"),4,1))) | AJ9: =IF(E9="","",VALUE(MID(TEXT(E9,"0000"),4,1))) | AK9: =IF(F9="","",VALUE(MID(TEXT(F9,"0000"),4,1))) | AL9: =IF(D9="","",IF(COUNTIF(AI9:AK9,">=5")=3,"🔴 全大",IF(COUNTIF(AI9:AK9,">=5")=0,"🔵 全小",IF(COUNTIF(AI9:AK9,">=5")=2,"▲ 偏大","▼ 偏小")))) | AM9: =IF(D9="","",IF((MOD(AI9,2)=1)+(MOD(AJ9,2)=1)+(MOD(AK9,2)=1)=3,"⚫ 全单",IF((MOD(AI9,2)=1)+(MOD(AJ9,2)=1)+(MOD(AK9,2)=1)=0,"🟣 全双",IF((MOD(AI9,2)=1)+(MOD(AJ9,2)=1)+(MOD(AK9,2)=1)=2,"◑ 偏单","◑ 偏双")))) | AN9: =IF(D9="","",IF(D8="",1,IF(ISNUMBER(SEARCH("大",AL9))=ISNUMBER(SEARCH("大",AL8)),AN8+1,1))) | AO9: =IF(AN9="","",IF(AN9>=4,"🚨 "&AN9&"期·警惕反转",IF(AN9=3,"⚠️ 3期连续","—"))) | AP9: =IF(AL9="","—",IF(ISNUMBER(SEARCH("大",AL9)),IF(OR(AL9="🔴 全大"),IF(AN9>=4,"xxx大 强·⚠️反转?",IF(AN9=3,"xxx大 强·连3期","xxx大 ✅强用")),"xxx大 △弱参考"),IF(OR(AL9="🔵 全小"),IF(AN9>=4,"xxx小 强·⚠️反转?",IF(AN9=3,"xxx小 强·连3期","xxx小 ✅强用")),"xxx小 △弱参考"))) | AR9: =IF(OR(D9="",D8=""),"—",IF(K8="","—",IF(ISNUMBER(SEARCH("大",K8)),IF(COUNTIF(H9:J9,">=5")>=2,"✅","❌"),IF(COUNTIF(H9:J9,">=5")<=1,"✅","❌")))) | AS9: =IF(OR(D9="",D8=""),"—",IF(T8="","—",IF(ISNUMBER(SEARCH("大",T8)),IF(COUNTIF(Q9:S9,">=5")>=2,"✅","❌"),IF(COUNTIF(Q9:S9,">=5")<=1,"✅","❌")))) | AT9: =IF(OR(D9="",D8=""),"—",IF(AC8="","—",IF(ISNUMBER(SEARCH("大",AC8)),IF(COUNTIF(Z9:AB9,">=5")>=2,"✅","❌"),IF(COUNTIF(Z9:AB9,">=5")<=1,"✅","❌")))) | AU9: =IF(OR(D9="",D8=""),"—",IF(AL8="","—",IF(ISNUMBER(SEARCH("大",AL8)),IF(COUNTIF(AI9:AK9,">=5")>=2,"✅","❌"),IF(COUNTIF(AI9:AK9,">=5")<=1,"✅","❌"))))
